Workbook

Sheet Инструкция
A1: НОРМЫ РАСХОДОВ НА ПРОИЗВОДСТВО
A2: Универсальный шаблон с разделением на переменные и постоянные затраты
A4: ГЛАВНАЯ ИДЕЯ ШАБЛОНА
A6: Все затраты разделены на ДВЕ ГРУППЫ по способу нормирования:
A8: 🔵 ГРУППА А — ПЕРЕМЕННЫЕ ЗАТРАТЫ (на 1 единицу продукции)
A9: Расход зависит от объёма выпуска. Произвели больше → потратили больше.
A10: Норма: например, "4 г полипропилена на 1 шприц".
A12: 🟠 ГРУППА Б — ПОСТОЯННЫЕ ЗАТРАТЫ (на период)
A13: Расход не зависит напрямую от количества единиц. Нормируется на месяц/год/срок службы.
A14: Норма: например, "20 л масла на машину раз в квартал" или "пресс-форма на 1 млн циклов".
A15: Шаблон автоматически пересчитывает эти затраты на 1 единицу продукции через объём выпуска.
A17: 🟢 СВОДКА — Полная себестоимость 1 единицы продукции (А + Б)
A20: СТРУКТУРА ШАБЛОНА
A21: Лист | B21: Описание | D21: Тип нормы
A22: — ОБЩЕЕ —
A23: Продукт | B23: Параметры продукта и объём выпуска
A24: — ГРУППА А: ПЕРЕМЕННЫЕ ЗАТРАТЫ — | D24: 🔵
A25: А1. Сырьё | B25: Основное сырьё (полимеры, металл, ткань, мука и т.д.) | D25: на 1 ед.
A26: А2. Вспом материалы | B26: Добавки, красители, реактивы | D26: на 1 ед.
A27: А3. Упаковка | B27: Тара, плёнка, этикетки, коробки | D27: на 1 ед.
A28: А4. Комплектующие | B28: Готовые детали, крепёж, электроника | D28: на 1 ед.
A29: А5. Энергоресурсы | B29: Электричество, вода, газ, пар (производственные) | D29: на 1 ед.
A30: А6. Отходы | B30: % потерь сырья + стоимость утилизации | D30: % от сырья
A31: — ГРУППА Б: ПОСТОЯННЫЕ ЗАТРАТЫ — | D31: 🟠
A32: Б1. Оборудование | B32: Амортизация основных средств (станки, линии) | D32: на период
A33: Б2. Оснастка | B33: Износ форм, штампов, инструмента (по циклам/времени) | D33: на период
A34: Б3. Запчасти | B34: ЗИП с интервалом замены | D34: на период
A35: Б4. Расходники | B35: Масла, СОЖ, фильтры (по моточасам/периоду) | D35: на период
A36: Б5. Материалы ТОиР | B36: Герметики, краски, изоляция для ремонта | D36: на период
A37: Б6. СИЗ и санитария | B37: Перчатки, спецодежда, моющие (на чел/мес) | D37: на период
A38: Б7. Услуги | B38: Логистика, сертификация, IT, аутсорс | D38: на период
A39: Б8. Прочее | B39: Любые позиции, не вошедшие выше | D39: —
A40: — ИТОГ — | D40: 🟢
A41: Сводка | B41: Полная себестоимость 1 ед. = А + Б
A44: ЦВЕТОВАЯ ЛЕГЕНДА
B45: Заголовки группы А (переменные затраты)
B46: Заголовки группы Б (постоянные затраты)
B47: Подкатегории группы А
B48: Подкатегории группы Б
B49: Поля "ДОБАВИТЬ ЕЩЁ ПУНКТ"
...

Sheet Продукт
A1: ИНФОРМАЦИЯ О ПРОДУКТЕ И ПЕРИОДЕ
A3: Параметр | B3: Значение | C3: Комментарий / пример
A4: Наименование продукта | C4: Например: Шприц одноразовый 10мл
A5: Артикул / Код продукта
A6: Единица измерения готовой продукции | B6: шт | C6: шт, кг, л, м, упаковка
A7: Плановый объём выпуска за период | B7: 100000 | C7: ⚠ Используется в формулах! Не оставляйте пустым
A8: Период (день/месяц/год) | B8: месяц
A9: Длительность периода в месяцах | B9: 1 | C9: Для пересчёта годовых затрат (1=месяц, 12=год)
A10: Количество рабочих дней в периоде | B10: 22 | C10: Для расчёта расхода по дням
A11: Количество рабочих часов в периоде | B11: 176 | C11: Для расчёта расхода по моточасам
A12: Численность производственного персонала | B12: 10 | C12: Для расчёта расхода СИЗ
A13: Количество единиц оборудования | B13: 5 | C13: Для общих расчётов
A14: Дата составления норм
A15: Ответственный (ФИО)

Sheet А1 Сырьё
A1: 🔵 А1. СЫРЬЁ (ОСНОВНОЕ) (норма на 1 ед. продукции)
A2: Жёлтые ячейки — обязательно заполнить (норма + цена). Стоимость считается автоматически.
A4: № | B4: Подкатегория / группа | C4: Наименование позиции | D4: Артикул / код | E4: Ед. изм. | F4: Норма расхода на 1 ед. продукции | G4: % потерь / отходов | H4: Норма с учётом потерь | I4: Цена за единицу | J4: Стоимость на 1 ед. продукции | K4: Стоимость на весь объём выпуска | L4: Поставщик | M4: Срок поставки (дней) | N4: Мин. складской запас | O4: Примечание
A5: Полимеры и пластмассы
A6: 1 | B6: Полимеры и пластмассы | C6: Полипропилен (гранулят) | E6: кг | H6: =IF(F6="","",F6*(1+IFERROR(G6,0))) | J6: =IFERROR(H6*I6,"") | K6: =IFERROR(J6*Продукт!B7,"")
A7: 2 | B7: Полимеры и пластмассы | C7: Полиэтилен низкого давления | E7: кг | H7: =IF(F7="","",F7*(1+IFERROR(G7,0))) | J7: =IFERROR(H7*I7,"") | K7: =IFERROR(J7*Продукт!B7,"")
A8: 3 | B8: Полимеры и пластмассы | H8: =IF(F8="","",F8*(1+IFERROR(G8,0))) | J8: =IFERROR(H8*I8,"") | K8: =IFERROR(J8*Продукт!B7,"")
A9: 4 | B9: Полимеры и пластмассы | H9: =IF(F9="","",F9*(1+IFERROR(G9,0))) | J9: =IFERROR(H9*I9,"") | K9: =IFERROR(J9*Продукт!B7,"")
A10: 5 | B10: Полимеры и пластмассы | H10: =IF(F10="","",F10*(1+IFERROR(G10,0))) | J10: =IFERROR(H10*I10,"") | K10: =IFERROR(J10*Продукт!B7,"")
A11: 6 | B11: Полимеры и пластмассы | H11: =IF(F11="","",F11*(1+IFERROR(G11,0))) | J11: =IFERROR(H11*I11,"") | K11: =IFERROR(J11*Продукт!B7,"")
A12: 7 | B12: Полимеры и пластмассы | H12: =IF(F12="","",F12*(1+IFERROR(G12,0))) | J12: =IFERROR(H12*I12,"") | K12: =IFERROR(J12*Продукт!B7,"")
A13: Металлы и сплавы
A14: 8 | B14: Металлы и сплавы | C14: Сталь листовая | E14: кг | H14: =IF(F14="","",F14*(1+IFERROR(G14,0))) | J14: =IFERROR(H14*I14,"") | K14: =IFERROR(J14*Продукт!B7,"")
A15: 9 | B15: Металлы и сплавы | H15: =IF(F15="","",F15*(1+IFERROR(G15,0))) | J15: =IFERROR(H15*I15,"") | K15: =IFERROR(J15*Продукт!B7,"")
A16: 10 | B16: Металлы и сплавы | H16: =IF(F16="","",F16*(1+IFERROR(G16,0))) | J16: =IFERROR(H16*I16,"") | K16: =IFERROR(J16*Продукт!B7,"")
A17: 11 | B17: Металлы и сплавы | H17: =IF(F17="","",F17*(1+IFERROR(G17,0))) | J17: =IFERROR(H17*I17,"") | K17: =IFERROR(J17*Продукт!B7,"")
A18: 12 | B18: Металлы и сплавы | H18: =IF(F18="","",F18*(1+IFERROR(G18,0))) | J18: =IFERROR(H18*I18,"") | K18: =IFERROR(J18*Продукт!B7,"")
A19: 13 | B19: Металлы и сплавы | H19: =IF(F19="","",F19*(1+IFERROR(G19,0))) | J19: =IFERROR(H19*I19,"") | K19: =IFERROR(J19*Продукт!B7,"")
A20: Древесина и изделия
A21: 14 | B21: Древесина и изделия | C21: Древесина (доска) | E21: м³ | H21: =IF(F21="","",F21*(1+IFERROR(G21,0))) | J21: =IFERROR(H21*I21,"") | K21: =IFERROR(J21*Продукт!B7,"")
A22: 15 | B22: Древесина и изделия | H22: =IF(F22="","",F22*(1+IFERROR(G22,0))) | J22: =IFERROR(H22*I22,"") | K22: =IFERROR(J22*Продукт!B7,"")
A23: 16 | B23: Древесина и изделия | H23: =IF(F23="","",F23*(1+IFERROR(G23,0))) | J23: =IFERROR(H23*I23,"") | K23: =IFERROR(J23*Продукт!B7,"")
A24: 17 | B24: Древесина и изделия | H24: =IF(F24="","",F24*(1+IFERROR(G24,0))) | J24: =IFERROR(H24*I24,"") | K24: =IFERROR(J24*Продукт!B7,"")
A25: 18 | B25: Древесина и изделия | H25: =IF(F25="","",F25*(1+IFERROR(G25,0))) | J25: =IFERROR(H25*I25,"") | K25: =IFERROR(J25*Продукт!B7,"")
A26: 19 | B26: Древесина и изделия | H26: =IF(F26="","",F26*(1+IFERROR(G26,0))) | J26: =IFERROR(H26*I26,"") | K26: =IFERROR(J26*Продукт!B7,"")
A27: Текстиль и волокна
A28: 20 | B28: Текстиль и волокна | C28: Ткань | E28: м | H28: =IF(F28="","",F28*(1+IFERROR(G28,0))) | J28: =IFERROR(H28*I28,"") | K28: =IFERROR(J28*Продукт!B7,"")
A29: 21 | B29: Текстиль и волокна | H29: =IF(F29="","",F29*(1+IFERROR(G29,0))) | J29: =IFERROR(H29*I29,"") | K29: =IFERROR(J29*Продукт!B7,"")
A30: 22 | B30: Текстиль и волокна | H30: =IF(F30="","",F30*(1+IFERROR(G30,0))) | J30: =IFERROR(H30*I30,"") | K30: =IFERROR(J30*Продукт!B7,"")
A31: 23 | B31: Текстиль и волокна | H31: =IF(F31="","",F31*(1+IFERROR(G31,0))) | J31: =IFERROR(H31*I31,"") | K31: =IFERROR(J31*Продукт!B7,"")
A32: 24 | B32: Текстиль и волокна | H32: =IF(F32="","",F32*(1+IFERROR(G32,0))) | J32: =IFERROR(H32*I32,"") | K32: =IFERROR(J32*Продукт!B7,"")
A33: 25 | B33: Текстиль и волокна | H33: =IF(F33="","",F33*(1+IFERROR(G33,0))) | J33: =IFERROR(H33*I33,"") | K33: =IFERROR(J33*Продукт!B7,"")
A34: Пищевое сырьё
A35: 26 | B35: Пищевое сырьё | C35: Мука | E35: кг | H35: =IF(F35="","",F35*(1+IFERROR(G35,0))) | J35: =IFERROR(H35*I35,"") | K35: =IFERROR(J35*Продукт!B7,"")
A36: 27 | B36: Пищевое сырьё | H36: =IF(F36="","",F36*(1+IFERROR(G36,0))) | J36: =IFERROR(H36*I36,"") | K36: =IFERROR(J36*Продукт!B7,"")
A37: 28 | B37: Пищевое сырьё | H37: =IF(F37="","",F37*(1+IFERROR(G37,0))) | J37: =IFERROR(H37*I37,"") | K37: =IFERROR(J37*Продукт!B7,"")
A38: 29 | B38: Пищевое сырьё | H38: =IF(F38="","",F38*(1+IFERROR(G38,0))) | J38: =IFERROR(H38*I38,"") | K38: =IFERROR(J38*Продукт!B7,"")
A39: 30 | B39: Пищевое сырьё | H39: =IF(F39="","",F39*(1+IFERROR(G39,0))) | J39: =IFERROR(H39*I39,"") | K39: =IFERROR(J39*Продукт!B7,"")
A40: 31 | B40: Пищевое сырьё | H40: =IF(F40="","",F40*(1+IFERROR(G40,0))) | J40: =IFERROR(H40*I40,"") | K40: =IFERROR(J40*Продукт!B7,"")
A41: Химическое сырьё
...

Sheet А2 Вспом материалы
A1: 🔵 А2. ВСПОМОГАТЕЛЬНЫЕ МАТЕРИАЛЫ (норма на 1 ед. продукции)
A2: Жёлтые ячейки — обязательно заполнить (норма + цена). Стоимость считается автоматически.
A4: № | B4: Подкатегория / группа | C4: Наименование позиции | D4: Артикул / код | E4: Ед. изм. | F4: Норма расхода на 1 ед. продукции | G4: % потерь / отходов | H4: Норма с учётом потерь | I4: Цена за единицу | J4: Стоимость на 1 ед. продукции | K4: Стоимость на весь объём выпуска | L4: Поставщик | M4: Срок поставки (дней) | N4: Мин. складской запас | O4: Примечание
A5: Добавки и модификаторы
A6: 1 | B6: Добавки и модификаторы | C6: Карбамид (скользящая добавка) | E6: кг | H6: =IF(F6="","",F6*(1+IFERROR(G6,0))) | J6: =IFERROR(H6*I6,"") | K6: =IFERROR(J6*Продукт!B7,"")
A7: 2 | B7: Добавки и модификаторы | C7: Краситель / пигмент | E7: кг | H7: =IF(F7="","",F7*(1+IFERROR(G7,0))) | J7: =IFERROR(H7*I7,"") | K7: =IFERROR(J7*Продукт!B7,"")
A8: 3 | B8: Добавки и модификаторы | C8: Стабилизатор | E8: кг | H8: =IF(F8="","",F8*(1+IFERROR(G8,0))) | J8: =IFERROR(H8*I8,"") | K8: =IFERROR(J8*Продукт!B7,"")
A9: 4 | B9: Добавки и модификаторы | H9: =IF(F9="","",F9*(1+IFERROR(G9,0))) | J9: =IFERROR(H9*I9,"") | K9: =IFERROR(J9*Продукт!B7,"")
A10: 5 | B10: Добавки и модификаторы | H10: =IF(F10="","",F10*(1+IFERROR(G10,0))) | J10: =IFERROR(H10*I10,"") | K10: =IFERROR(J10*Продукт!B7,"")
A11: 6 | B11: Добавки и модификаторы | H11: =IF(F11="","",F11*(1+IFERROR(G11,0))) | J11: =IFERROR(H11*I11,"") | K11: =IFERROR(J11*Продукт!B7,"")
A12: 7 | B12: Добавки и модификаторы | H12: =IF(F12="","",F12*(1+IFERROR(G12,0))) | J12: =IFERROR(H12*I12,"") | K12: =IFERROR(J12*Продукт!B7,"")
A13: 8 | B13: Добавки и модификаторы | H13: =IF(F13="","",F13*(1+IFERROR(G13,0))) | J13: =IFERROR(H13*I13,"") | K13: =IFERROR(J13*Продукт!B7,"")
A14: Клеи, герметики технологические
A15: 9 | B15: Клеи, герметики технологические | C15: Клей промышленный | E15: кг | H15: =IF(F15="","",F15*(1+IFERROR(G15,0))) | J15: =IFERROR(H15*I15,"") | K15: =IFERROR(J15*Продукт!B7,"")
A16: 10 | B16: Клеи, герметики технологические | H16: =IF(F16="","",F16*(1+IFERROR(G16,0))) | J16: =IFERROR(H16*I16,"") | K16: =IFERROR(J16*Продукт!B7,"")
A17: 11 | B17: Клеи, герметики технологические | H17: =IF(F17="","",F17*(1+IFERROR(G17,0))) | J17: =IFERROR(H17*I17,"") | K17: =IFERROR(J17*Продукт!B7,"")
A18: 12 | B18: Клеи, герметики технологические | H18: =IF(F18="","",F18*(1+IFERROR(G18,0))) | J18: =IFERROR(H18*I18,"") | K18: =IFERROR(J18*Продукт!B7,"")
A19: 13 | B19: Клеи, герметики технологические | H19: =IF(F19="","",F19*(1+IFERROR(G19,0))) | J19: =IFERROR(H19*I19,"") | K19: =IFERROR(J19*Продукт!B7,"")
A20: 14 | B20: Клеи, герметики технологические | H20: =IF(F20="","",F20*(1+IFERROR(G20,0))) | J20: =IFERROR(H20*I20,"") | K20: =IFERROR(J20*Продукт!B7,"")
A21: Реактивы процесса
A22: 15 | B22: Реактивы процесса | C22: Реактив технологический | E22: кг | H22: =IF(F22="","",F22*(1+IFERROR(G22,0))) | J22: =IFERROR(H22*I22,"") | K22: =IFERROR(J22*Продукт!B7,"")
A23: 16 | B23: Реактивы процесса | H23: =IF(F23="","",F23*(1+IFERROR(G23,0))) | J23: =IFERROR(H23*I23,"") | K23: =IFERROR(J23*Продукт!B7,"")
A24: 17 | B24: Реактивы процесса | H24: =IF(F24="","",F24*(1+IFERROR(G24,0))) | J24: =IFERROR(H24*I24,"") | K24: =IFERROR(J24*Продукт!B7,"")
A25: 18 | B25: Реактивы процесса | H25: =IF(F25="","",F25*(1+IFERROR(G25,0))) | J25: =IFERROR(H25*I25,"") | K25: =IFERROR(J25*Продукт!B7,"")
A26: 19 | B26: Реактивы процесса | H26: =IF(F26="","",F26*(1+IFERROR(G26,0))) | J26: =IFERROR(H26*I26,"") | K26: =IFERROR(J26*Продукт!B7,"")
A27: 20 | B27: Реактивы процесса | H27: =IF(F27="","",F27*(1+IFERROR(G27,0))) | J27: =IFERROR(H27*I27,"") | K27: =IFERROR(J27*Продукт!B7,"")
A28: + ДОБАВИТЬ ЕЩЁ ПУНКТ (вставляйте строки выше или дописывайте здесь)
A29: 21 | H29: =IF(F29="","",F29*(1+IFERROR(G29,0))) | J29: =IFERROR(H29*I29,"") | K29: =IFERROR(J29*Продукт!B7,"")
A30: 22 | H30: =IF(F30="","",F30*(1+IFERROR(G30,0))) | J30: =IFERROR(H30*I30,"") | K30: =IFERROR(J30*Продукт!B7,"")
A31: 23 | H31: =IF(F31="","",F31*(1+IFERROR(G31,0))) | J31: =IFERROR(H31*I31,"") | K31: =IFERROR(J31*Продукт!B7,"")
A32: 24 | H32: =IF(F32="","",F32*(1+IFERROR(G32,0))) | J32: =IFERROR(H32*I32,"") | K32: =IFERROR(J32*Продукт!B7,"")
A33: 25 | H33: =IF(F33="","",F33*(1+IFERROR(G33,0))) | J33: =IFERROR(H33*I33,"") | K33: =IFERROR(J33*Продукт!B7,"")
A35: ИТОГО ПО КАТЕГОРИИ: | J35: =SUMIF(J5:J33,">0") -> 0 | K35: =SUMIF(K5:K33,">0") -> 0

Sheet А3 Упаковка
A1: 🔵 А3. УПАКОВКА (норма на 1 ед. продукции)
A2: Жёлтые ячейки — обязательно заполнить (норма + цена). Стоимость считается автоматически.
A4: № | B4: Подкатегория / группа | C4: Наименование позиции | D4: Артикул / код | E4: Ед. изм. | F4: Норма расхода на 1 ед. продукции | G4: % потерь / отходов | H4: Норма с учётом потерь | I4: Цена за единицу | J4: Стоимость на 1 ед. продукции | K4: Стоимость на весь объём выпуска | L4: Поставщик | M4: Срок поставки (дней) | N4: Мин. складской запас | O4: Примечание
A5: Первичная упаковка
A6: 1 | B6: Первичная упаковка | C6: Блистерная плёнка | E6: м² | H6: =IF(F6="","",F6*(1+IFERROR(G6,0))) | J6: =IFERROR(H6*I6,"") | K6: =IFERROR(J6*Продукт!B7,"")
A7: 2 | B7: Первичная упаковка | C7: Бумага газостерилизуемая | E7: м² | H7: =IF(F7="","",F7*(1+IFERROR(G7,0))) | J7: =IFERROR(H7*I7,"") | K7: =IFERROR(J7*Продукт!B7,"")
A8: 3 | B8: Первичная упаковка | C8: Пакет/банка/флакон | E8: шт | H8: =IF(F8="","",F8*(1+IFERROR(G8,0))) | J8: =IFERROR(H8*I8,"") | K8: =IFERROR(J8*Продукт!B7,"")
A9: 4 | B9: Первичная упаковка | H9: =IF(F9="","",F9*(1+IFERROR(G9,0))) | J9: =IFERROR(H9*I9,"") | K9: =IFERROR(J9*Продукт!B7,"")
A10: 5 | B10: Первичная упаковка | H10: =IF(F10="","",F10*(1+IFERROR(G10,0))) | J10: =IFERROR(H10*I10,"") | K10: =IFERROR(J10*Продукт!B7,"")
A11: 6 | B11: Первичная упаковка | H11: =IF(F11="","",F11*(1+IFERROR(G11,0))) | J11: =IFERROR(H11*I11,"") | K11: =IFERROR(J11*Продукт!B7,"")
A12: 7 | B12: Первичная упаковка | H12: =IF(F12="","",F12*(1+IFERROR(G12,0))) | J12: =IFERROR(H12*I12,"") | K12: =IFERROR(J12*Продукт!B7,"")
A13: 8 | B13: Первичная упаковка | H13: =IF(F13="","",F13*(1+IFERROR(G13,0))) | J13: =IFERROR(H13*I13,"") | K13: =IFERROR(J13*Продукт!B7,"")
A14: Вторичная упаковка
A15: 9 | B15: Вторичная упаковка | C15: Коробка картонная | E15: шт | H15: =IF(F15="","",F15*(1+IFERROR(G15,0))) | J15: =IFERROR(H15*I15,"") | K15: =IFERROR(J15*Продукт!B7,"")
A16: 10 | B16: Вторичная упаковка | C16: Этикетка | E16: шт | H16: =IF(F16="","",F16*(1+IFERROR(G16,0))) | J16: =IFERROR(H16*I16,"") | K16: =IFERROR(J16*Продукт!B7,"")
A17: 11 | B17: Вторичная упаковка | C17: Инструкция (вкладыш) | E17: шт | H17: =IF(F17="","",F17*(1+IFERROR(G17,0))) | J17: =IFERROR(H17*I17,"") | K17: =IFERROR(J17*Продукт!B7,"")
A18: 12 | B18: Вторичная упаковка | H18: =IF(F18="","",F18*(1+IFERROR(G18,0))) | J18: =IFERROR(H18*I18,"") | K18: =IFERROR(J18*Продукт!B7,"")
A19: 13 | B19: Вторичная упаковка | H19: =IF(F19="","",F19*(1+IFERROR(G19,0))) | J19: =IFERROR(H19*I19,"") | K19: =IFERROR(J19*Продукт!B7,"")
A20: 14 | B20: Вторичная упаковка | H20: =IF(F20="","",F20*(1+IFERROR(G20,0))) | J20: =IFERROR(H20*I20,"") | K20: =IFERROR(J20*Продукт!B7,"")
A21: 15 | B21: Вторичная упаковка | H21: =IF(F21="","",F21*(1+IFERROR(G21,0))) | J21: =IFERROR(H21*I21,"") | K21: =IFERROR(J21*Продукт!B7,"")
A22: 16 | B22: Вторичная упаковка | H22: =IF(F22="","",F22*(1+IFERROR(G22,0))) | J22: =IFERROR(H22*I22,"") | K22: =IFERROR(J22*Продукт!B7,"")
A23: Транспортная упаковка
A24: 17 | B24: Транспортная упаковка | C24: Гофрокороб | E24: шт | H24: =IF(F24="","",F24*(1+IFERROR(G24,0))) | J24: =IFERROR(H24*I24,"") | K24: =IFERROR(J24*Продукт!B7,"")
A25: 18 | B25: Транспортная упаковка | C25: Стрейч-плёнка | E25: м | H25: =IF(F25="","",F25*(1+IFERROR(G25,0))) | J25: =IFERROR(H25*I25,"") | K25: =IFERROR(J25*Продукт!B7,"")
A26: 19 | B26: Транспортная упаковка | C26: Скотч упаковочный | E26: м | H26: =IF(F26="","",F26*(1+IFERROR(G26,0))) | J26: =IFERROR(H26*I26,"") | K26: =IFERROR(J26*Продукт!B7,"")
A27: 20 | B27: Транспортная упаковка | C27: Паллета деревянная | E27: шт | H27: =IF(F27="","",F27*(1+IFERROR(G27,0))) | J27: =IFERROR(H27*I27,"") | K27: =IFERROR(J27*Продукт!B7,"")
A28: 21 | B28: Транспортная упаковка | H28: =IF(F28="","",F28*(1+IFERROR(G28,0))) | J28: =IFERROR(H28*I28,"") | K28: =IFERROR(J28*Продукт!B7,"")
A29: 22 | B29: Транспортная упаковка | H29: =IF(F29="","",F29*(1+IFERROR(G29,0))) | J29: =IFERROR(H29*I29,"") | K29: =IFERROR(J29*Продукт!B7,"")
A30: 23 | B30: Транспортная упаковка | H30: =IF(F30="","",F30*(1+IFERROR(G30,0))) | J30: =IFERROR(H30*I30,"") | K30: =IFERROR(J30*Продукт!B7,"")
A31: 24 | B31: Транспортная упаковка | H31: =IF(F31="","",F31*(1+IFERROR(G31,0))) | J31: =IFERROR(H31*I31,"") | K31: =IFERROR(J31*Продукт!B7,"")
A32: 25 | B32: Транспортная упаковка | H32: =IF(F32="","",F32*(1+IFERROR(G32,0))) | J32: =IFERROR(H32*I32,"") | K32: =IFERROR(J32*Продукт!B7,"")
A33: + ДОБАВИТЬ ЕЩЁ ПУНКТ (вставляйте строки выше или дописывайте здесь)
A34: 26 | H34: =IF(F34="","",F34*(1+IFERROR(G34,0))) | J34: =IFERROR(H34*I34,"") | K34: =IFERROR(J34*Продукт!B7,"")
A35: 27 | H35: =IF(F35="","",F35*(1+IFERROR(G35,0))) | J35: =IFERROR(H35*I35,"") | K35: =IFERROR(J35*Продукт!B7,"")
A36: 28 | H36: =IF(F36="","",F36*(1+IFERROR(G36,0))) | J36: =IFERROR(H36*I36,"") | K36: =IFERROR(J36*Продукт!B7,"")
A37: 29 | H37: =IF(F37="","",F37*(1+IFERROR(G37,0))) | J37: =IFERROR(H37*I37,"") | K37: =IFERROR(J37*Продукт!B7,"")
A38: 30 | H38: =IF(F38="","",F38*(1+IFERROR(G38,0))) | J38: =IFERROR(H38*I38,"") | K38: =IFERROR(J38*Продукт!B7,"")
A40: ИТОГО ПО КАТЕГОРИИ: | J40: =SUMIF(J5:J38,">0") -> 0 | K40: =SUMIF(K5:K38,">0") -> 0

Sheet А4 Комплектующие
A1: 🔵 А4. КОМПЛЕКТУЮЩИЕ И ПОЛУФАБРИКАТЫ (норма на 1 ед. продукции)
A2: Жёлтые ячейки — обязательно заполнить (норма + цена). Стоимость считается автоматически.
A4: № | B4: Подкатегория / группа | C4: Наименование позиции | D4: Артикул / код | E4: Ед. изм. | F4: Норма расхода на 1 ед. продукции | G4: % потерь / отходов | H4: Норма с учётом потерь | I4: Цена за единицу | J4: Стоимость на 1 ед. продукции | K4: Стоимость на весь объём выпуска | L4: Поставщик | M4: Срок поставки (дней) | N4: Мин. складской запас | O4: Примечание
A5: Готовые детали (покупные)
A6: 1 | B6: Готовые детали (покупные) | C6: Деталь / узел | E6: шт | H6: =IF(F6="","",F6*(1+IFERROR(G6,0))) | J6: =IFERROR(H6*I6,"") | K6: =IFERROR(J6*Продукт!B7,"")
A7: 2 | B7: Готовые детали (покупные) | H7: =IF(F7="","",F7*(1+IFERROR(G7,0))) | J7: =IFERROR(H7*I7,"") | K7: =IFERROR(J7*Продукт!B7,"")
A8: 3 | B8: Готовые детали (покупные) | H8: =IF(F8="","",F8*(1+IFERROR(G8,0))) | J8: =IFERROR(H8*I8,"") | K8: =IFERROR(J8*Продукт!B7,"")
A9: 4 | B9: Готовые детали (покупные) | H9: =IF(F9="","",F9*(1+IFERROR(G9,0))) | J9: =IFERROR(H9*I9,"") | K9: =IFERROR(J9*Продукт!B7,"")
A10: 5 | B10: Готовые детали (покупные) | H10: =IF(F10="","",F10*(1+IFERROR(G10,0))) | J10: =IFERROR(H10*I10,"") | K10: =IFERROR(J10*Продукт!B7,"")
A11: 6 | B11: Готовые детали (покупные) | H11: =IF(F11="","",F11*(1+IFERROR(G11,0))) | J11: =IFERROR(H11*I11,"") | K11: =IFERROR(J11*Продукт!B7,"")
A12: Крепёж и метизы
A13: 7 | B13: Крепёж и метизы | C13: Винт / болт | E13: шт | H13: =IF(F13="","",F13*(1+IFERROR(G13,0))) | J13: =IFERROR(H13*I13,"") | K13: =IFERROR(J13*Продукт!B7,"")
A14: 8 | B14: Крепёж и метизы | C14: Гайка | E14: шт | H14: =IF(F14="","",F14*(1+IFERROR(G14,0))) | J14: =IFERROR(H14*I14,"") | K14: =IFERROR(J14*Продукт!B7,"")
A15: 9 | B15: Крепёж и метизы | H15: =IF(F15="","",F15*(1+IFERROR(G15,0))) | J15: =IFERROR(H15*I15,"") | K15: =IFERROR(J15*Продукт!B7,"")
A16: 10 | B16: Крепёж и метизы | H16: =IF(F16="","",F16*(1+IFERROR(G16,0))) | J16: =IFERROR(H16*I16,"") | K16: =IFERROR(J16*Продукт!B7,"")
A17: 11 | B17: Крепёж и метизы | H17: =IF(F17="","",F17*(1+IFERROR(G17,0))) | J17: =IFERROR(H17*I17,"") | K17: =IFERROR(J17*Продукт!B7,"")
A18: 12 | B18: Крепёж и метизы | H18: =IF(F18="","",F18*(1+IFERROR(G18,0))) | J18: =IFERROR(H18*I18,"") | K18: =IFERROR(J18*Продукт!B7,"")
A19: 13 | B19: Крепёж и метизы | H19: =IF(F19="","",F19*(1+IFERROR(G19,0))) | J19: =IFERROR(H19*I19,"") | K19: =IFERROR(J19*Продукт!B7,"")
A20: Электронные компоненты
A21: 14 | B21: Электронные компоненты | C21: Плата / модуль | E21: шт | H21: =IF(F21="","",F21*(1+IFERROR(G21,0))) | J21: =IFERROR(H21*I21,"") | K21: =IFERROR(J21*Продукт!B7,"")
A22: 15 | B22: Электронные компоненты | H22: =IF(F22="","",F22*(1+IFERROR(G22,0))) | J22: =IFERROR(H22*I22,"") | K22: =IFERROR(J22*Продукт!B7,"")
A23: 16 | B23: Электронные компоненты | H23: =IF(F23="","",F23*(1+IFERROR(G23,0))) | J23: =IFERROR(H23*I23,"") | K23: =IFERROR(J23*Продукт!B7,"")
A24: 17 | B24: Электронные компоненты | H24: =IF(F24="","",F24*(1+IFERROR(G24,0))) | J24: =IFERROR(H24*I24,"") | K24: =IFERROR(J24*Продукт!B7,"")
A25: 18 | B25: Электронные компоненты | H25: =IF(F25="","",F25*(1+IFERROR(G25,0))) | J25: =IFERROR(H25*I25,"") | K25: =IFERROR(J25*Продукт!B7,"")
A26: 19 | B26: Электронные компоненты | H26: =IF(F26="","",F26*(1+IFERROR(G26,0))) | J26: =IFERROR(H26*I26,"") | K26: =IFERROR(J26*Продукт!B7,"")
A27: + ДОБАВИТЬ ЕЩЁ ПУНКТ (вставляйте строки выше или дописывайте здесь)
A28: 20 | H28: =IF(F28="","",F28*(1+IFERROR(G28,0))) | J28: =IFERROR(H28*I28,"") | K28: =IFERROR(J28*Продукт!B7,"")
A29: 21 | H29: =IF(F29="","",F29*(1+IFERROR(G29,0))) | J29: =IFERROR(H29*I29,"") | K29: =IFERROR(J29*Продукт!B7,"")
A30: 22 | H30: =IF(F30="","",F30*(1+IFERROR(G30,0))) | J30: =IFERROR(H30*I30,"") | K30: =IFERROR(J30*Продукт!B7,"")
A31: 23 | H31: =IF(F31="","",F31*(1+IFERROR(G31,0))) | J31: =IFERROR(H31*I31,"") | K31: =IFERROR(J31*Продукт!B7,"")
A32: 24 | H32: =IF(F32="","",F32*(1+IFERROR(G32,0))) | J32: =IFERROR(H32*I32,"") | K32: =IFERROR(J32*Продукт!B7,"")
A34: ИТОГО ПО КАТЕГОРИИ: | J34: =SUMIF(J5:J32,">0") -> 0 | K34: =SUMIF(K5:K32,">0") -> 0

Sheet А5 Энергоресурсы
A1: 🔵 А5. ЭНЕРГОРЕСУРСЫ (ПРОИЗВОДСТВЕННЫЕ) (норма на 1 ед. продукции)
A2: Жёлтые ячейки — обязательно заполнить (норма + цена). Стоимость считается автоматически.
A4: № | B4: Подкатегория / группа | C4: Наименование позиции | D4: Артикул / код | E4: Ед. изм. | F4: Норма расхода на 1 ед. продукции | G4: % потерь / отходов | H4: Норма с учётом потерь | I4: Цена за единицу | J4: Стоимость на 1 ед. продукции | K4: Стоимость на весь объём выпуска | L4: Поставщик | M4: Срок поставки (дней) | N4: Мин. складской запас | O4: Примечание
A5: Электричество
A6: 1 | B6: Электричество | C6: Электроэнергия | E6: кВт·ч | H6: =IF(F6="","",F6*(1+IFERROR(G6,0))) | J6: =IFERROR(H6*I6,"") | K6: =IFERROR(J6*Продукт!B7,"")
A7: 2 | B7: Электричество | H7: =IF(F7="","",F7*(1+IFERROR(G7,0))) | J7: =IFERROR(H7*I7,"") | K7: =IFERROR(J7*Продукт!B7,"")
A8: 3 | B8: Электричество | H8: =IF(F8="","",F8*(1+IFERROR(G8,0))) | J8: =IFERROR(H8*I8,"") | K8: =IFERROR(J8*Продукт!B7,"")
A9: 4 | B9: Электричество | H9: =IF(F9="","",F9*(1+IFERROR(G9,0))) | J9: =IFERROR(H9*I9,"") | K9: =IFERROR(J9*Продукт!B7,"")
A10: 5 | B10: Электричество | H10: =IF(F10="","",F10*(1+IFERROR(G10,0))) | J10: =IFERROR(H10*I10,"") | K10: =IFERROR(J10*Продукт!B7,"")
A11: 6 | B11: Электричество | H11: =IF(F11="","",F11*(1+IFERROR(G11,0))) | J11: =IFERROR(H11*I11,"") | K11: =IFERROR(J11*Продукт!B7,"")
A12: Газ и пар
A13: 7 | B13: Газ и пар | C13: Природный газ | E13: м³ | H13: =IF(F13="","",F13*(1+IFERROR(G13,0))) | J13: =IFERROR(H13*I13,"") | K13: =IFERROR(J13*Продукт!B7,"")
A14: 8 | B14: Газ и пар | C14: Пар технологический | E14: т | H14: =IF(F14="","",F14*(1+IFERROR(G14,0))) | J14: =IFERROR(H14*I14,"") | K14: =IFERROR(J14*Продукт!B7,"")
A15: 9 | B15: Газ и пар | H15: =IF(F15="","",F15*(1+IFERROR(G15,0))) | J15: =IFERROR(H15*I15,"") | K15: =IFERROR(J15*Продукт!B7,"")
A16: 10 | B16: Газ и пар | H16: =IF(F16="","",F16*(1+IFERROR(G16,0))) | J16: =IFERROR(H16*I16,"") | K16: =IFERROR(J16*Продукт!B7,"")
A17: 11 | B17: Газ и пар | H17: =IF(F17="","",F17*(1+IFERROR(G17,0))) | J17: =IFERROR(H17*I17,"") | K17: =IFERROR(J17*Продукт!B7,"")
A18: 12 | B18: Газ и пар | H18: =IF(F18="","",F18*(1+IFERROR(G18,0))) | J18: =IFERROR(H18*I18,"") | K18: =IFERROR(J18*Продукт!B7,"")
A19: 13 | B19: Газ и пар | H19: =IF(F19="","",F19*(1+IFERROR(G19,0))) | J19: =IFERROR(H19*I19,"") | K19: =IFERROR(J19*Продукт!B7,"")
A20: Вода
A21: 14 | B21: Вода | C21: Вода питьевая / техническая | E21: м³ | H21: =IF(F21="","",F21*(1+IFERROR(G21,0))) | J21: =IFERROR(H21*I21,"") | K21: =IFERROR(J21*Продукт!B7,"")
A22: 15 | B22: Вода | C22: Вода очищенная | E22: м³ | H22: =IF(F22="","",F22*(1+IFERROR(G22,0))) | J22: =IFERROR(H22*I22,"") | K22: =IFERROR(J22*Продукт!B7,"")
A23: 16 | B23: Вода | H23: =IF(F23="","",F23*(1+IFERROR(G23,0))) | J23: =IFERROR(H23*I23,"") | K23: =IFERROR(J23*Продукт!B7,"")
A24: 17 | B24: Вода | H24: =IF(F24="","",F24*(1+IFERROR(G24,0))) | J24: =IFERROR(H24*I24,"") | K24: =IFERROR(J24*Продукт!B7,"")
A25: 18 | B25: Вода | H25: =IF(F25="","",F25*(1+IFERROR(G25,0))) | J25: =IFERROR(H25*I25,"") | K25: =IFERROR(J25*Продукт!B7,"")
A26: 19 | B26: Вода | H26: =IF(F26="","",F26*(1+IFERROR(G26,0))) | J26: =IFERROR(H26*I26,"") | K26: =IFERROR(J26*Продукт!B7,"")
A27: 20 | B27: Вода | H27: =IF(F27="","",F27*(1+IFERROR(G27,0))) | J27: =IFERROR(H27*I27,"") | K27: =IFERROR(J27*Продукт!B7,"")
A28: Сжатый воздух и газы
A29: 21 | B29: Сжатый воздух и газы | C29: Сжатый воздух | E29: м³ | H29: =IF(F29="","",F29*(1+IFERROR(G29,0))) | J29: =IFERROR(H29*I29,"") | K29: =IFERROR(J29*Продукт!B7,"")
A30: 22 | B30: Сжатый воздух и газы | C30: Азот / аргон | E30: м³ | H30: =IF(F30="","",F30*(1+IFERROR(G30,0))) | J30: =IFERROR(H30*I30,"") | K30: =IFERROR(J30*Продукт!B7,"")
A31: 23 | B31: Сжатый воздух и газы | H31: =IF(F31="","",F31*(1+IFERROR(G31,0))) | J31: =IFERROR(H31*I31,"") | K31: =IFERROR(J31*Продукт!B7,"")
A32: 24 | B32: Сжатый воздух и газы | H32: =IF(F32="","",F32*(1+IFERROR(G32,0))) | J32: =IFERROR(H32*I32,"") | K32: =IFERROR(J32*Продукт!B7,"")
A33: 25 | B33: Сжатый воздух и газы | H33: =IF(F33="","",F33*(1+IFERROR(G33,0))) | J33: =IFERROR(H33*I33,"") | K33: =IFERROR(J33*Продукт!B7,"")
A34: 26 | B34: Сжатый воздух и газы | H34: =IF(F34="","",F34*(1+IFERROR(G34,0))) | J34: =IFERROR(H34*I34,"") | K34: =IFERROR(J34*Продукт!B7,"")
A35: 27 | B35: Сжатый воздух и газы | H35: =IF(F35="","",F35*(1+IFERROR(G35,0))) | J35: =IFERROR(H35*I35,"") | K35: =IFERROR(J35*Продукт!B7,"")
A36: + ДОБАВИТЬ ЕЩЁ ПУНКТ (вставляйте строки выше или дописывайте здесь)
A37: 28 | H37: =IF(F37="","",F37*(1+IFERROR(G37,0))) | J37: =IFERROR(H37*I37,"") | K37: =IFERROR(J37*Продукт!B7,"")
A38: 29 | H38: =IF(F38="","",F38*(1+IFERROR(G38,0))) | J38: =IFERROR(H38*I38,"") | K38: =IFERROR(J38*Продукт!B7,"")
A39: 30 | H39: =IF(F39="","",F39*(1+IFERROR(G39,0))) | J39: =IFERROR(H39*I39,"") | K39: =IFERROR(J39*Продукт!B7,"")
A40: 31 | H40: =IF(F40="","",F40*(1+IFERROR(G40,0))) | J40: =IFERROR(H40*I40,"") | K40: =IFERROR(J40*Продукт!B7,"")
A41: 32 | H41: =IF(F41="","",F41*(1+IFERROR(G41,0))) | J41: =IFERROR(H41*I41,"") | K41: =IFERROR(J41*Продукт!B7,"")
...

Sheet А6 Отходы
A1: 🔵 А6. ОТХОДЫ И УТИЛИЗАЦИЯ (норма на 1 ед. продукции)
A2: Жёлтые ячейки — обязательно заполнить (норма + цена). Стоимость считается автоматически.
A4: № | B4: Подкатегория / группа | C4: Наименование позиции | D4: Артикул / код | E4: Ед. изм. | F4: Норма расхода на 1 ед. продукции | G4: % потерь / отходов | H4: Норма с учётом потерь | I4: Цена за единицу | J4: Стоимость на 1 ед. продукции | K4: Стоимость на весь объём выпуска | L4: Поставщик | M4: Срок поставки (дней) | N4: Мин. складской запас | O4: Примечание
A5: Производственные отходы
A6: 1 | B6: Производственные отходы | C6: Полимерные обрезки (утилизация) | E6: кг | H6: =IF(F6="","",F6*(1+IFERROR(G6,0))) | J6: =IFERROR(H6*I6,"") | K6: =IFERROR(J6*Продукт!B7,"")
A7: 2 | B7: Производственные отходы | C7: Металлическая стружка (утилизация) | E7: кг | H7: =IF(F7="","",F7*(1+IFERROR(G7,0))) | J7: =IFERROR(H7*I7,"") | K7: =IFERROR(J7*Продукт!B7,"")
A8: 3 | B8: Производственные отходы | C8: Бракованная продукция (утилизация) | E8: шт | H8: =IF(F8="","",F8*(1+IFERROR(G8,0))) | J8: =IFERROR(H8*I8,"") | K8: =IFERROR(J8*Продукт!B7,"")
A9: 4 | B9: Производственные отходы | H9: =IF(F9="","",F9*(1+IFERROR(G9,0))) | J9: =IFERROR(H9*I9,"") | K9: =IFERROR(J9*Продукт!B7,"")
A10: 5 | B10: Производственные отходы | H10: =IF(F10="","",F10*(1+IFERROR(G10,0))) | J10: =IFERROR(H10*I10,"") | K10: =IFERROR(J10*Продукт!B7,"")
A11: 6 | B11: Производственные отходы | H11: =IF(F11="","",F11*(1+IFERROR(G11,0))) | J11: =IFERROR(H11*I11,"") | K11: =IFERROR(J11*Продукт!B7,"")
A12: 7 | B12: Производственные отходы | H12: =IF(F12="","",F12*(1+IFERROR(G12,0))) | J12: =IFERROR(H12*I12,"") | K12: =IFERROR(J12*Продукт!B7,"")
A13: 8 | B13: Производственные отходы | H13: =IF(F13="","",F13*(1+IFERROR(G13,0))) | J13: =IFERROR(H13*I13,"") | K13: =IFERROR(J13*Продукт!B7,"")
A14: Опасные отходы
A15: 9 | B15: Опасные отходы | C15: Отработанное масло (вывоз) | E15: л | H15: =IF(F15="","",F15*(1+IFERROR(G15,0))) | J15: =IFERROR(H15*I15,"") | K15: =IFERROR(J15*Продукт!B7,"")
A16: 10 | B16: Опасные отходы | C16: Загрязнённая ветошь, фильтры | E16: кг | H16: =IF(F16="","",F16*(1+IFERROR(G16,0))) | J16: =IFERROR(H16*I16,"") | K16: =IFERROR(J16*Продукт!B7,"")
A17: 11 | B17: Опасные отходы | H17: =IF(F17="","",F17*(1+IFERROR(G17,0))) | J17: =IFERROR(H17*I17,"") | K17: =IFERROR(J17*Продукт!B7,"")
A18: 12 | B18: Опасные отходы | H18: =IF(F18="","",F18*(1+IFERROR(G18,0))) | J18: =IFERROR(H18*I18,"") | K18: =IFERROR(J18*Продукт!B7,"")
A19: 13 | B19: Опасные отходы | H19: =IF(F19="","",F19*(1+IFERROR(G19,0))) | J19: =IFERROR(H19*I19,"") | K19: =IFERROR(J19*Продукт!B7,"")
A20: 14 | B20: Опасные отходы | H20: =IF(F20="","",F20*(1+IFERROR(G20,0))) | J20: =IFERROR(H20*I20,"") | K20: =IFERROR(J20*Продукт!B7,"")
A21: 15 | B21: Опасные отходы | H21: =IF(F21="","",F21*(1+IFERROR(G21,0))) | J21: =IFERROR(H21*I21,"") | K21: =IFERROR(J21*Продукт!B7,"")
A22: Возврат от вторсырья (доход — со знаком минус в цене)
A23: 16 | B23: Возврат от вторсырья (доход — со знаком минус в цене) | C23: Металлолом на сдачу | E23: кг | H23: =IF(F23="","",F23*(1+IFERROR(G23,0))) | J23: =IFERROR(H23*I23,"") | K23: =IFERROR(J23*Продукт!B7,"")
A24: 17 | B24: Возврат от вторсырья (доход — со знаком минус в цене) | C24: Полимер на переработку | E24: кг | H24: =IF(F24="","",F24*(1+IFERROR(G24,0))) | J24: =IFERROR(H24*I24,"") | K24: =IFERROR(J24*Продукт!B7,"")
A25: 18 | B25: Возврат от вторсырья (доход — со знаком минус в цене) | H25: =IF(F25="","",F25*(1+IFERROR(G25,0))) | J25: =IFERROR(H25*I25,"") | K25: =IFERROR(J25*Продукт!B7,"")
A26: 19 | B26: Возврат от вторсырья (доход — со знаком минус в цене) | H26: =IF(F26="","",F26*(1+IFERROR(G26,0))) | J26: =IFERROR(H26*I26,"") | K26: =IFERROR(J26*Продукт!B7,"")
A27: 20 | B27: Возврат от вторсырья (доход — со знаком минус в цене) | H27: =IF(F27="","",F27*(1+IFERROR(G27,0))) | J27: =IFERROR(H27*I27,"") | K27: =IFERROR(J27*Продукт!B7,"")
A28: 21 | B28: Возврат от вторсырья (доход — со знаком минус в цене) | H28: =IF(F28="","",F28*(1+IFERROR(G28,0))) | J28: =IFERROR(H28*I28,"") | K28: =IFERROR(J28*Продукт!B7,"")
A29: 22 | B29: Возврат от вторсырья (доход — со знаком минус в цене) | H29: =IF(F29="","",F29*(1+IFERROR(G29,0))) | J29: =IFERROR(H29*I29,"") | K29: =IFERROR(J29*Продукт!B7,"")
A30: + ДОБАВИТЬ ЕЩЁ ПУНКТ (вставляйте строки выше или дописывайте здесь)
A31: 23 | H31: =IF(F31="","",F31*(1+IFERROR(G31,0))) | J31: =IFERROR(H31*I31,"") | K31: =IFERROR(J31*Продукт!B7,"")
A32: 24 | H32: =IF(F32="","",F32*(1+IFERROR(G32,0))) | J32: =IFERROR(H32*I32,"") | K32: =IFERROR(J32*Продукт!B7,"")
A33: 25 | H33: =IF(F33="","",F33*(1+IFERROR(G33,0))) | J33: =IFERROR(H33*I33,"") | K33: =IFERROR(J33*Продукт!B7,"")
A34: 26 | H34: =IF(F34="","",F34*(1+IFERROR(G34,0))) | J34: =IFERROR(H34*I34,"") | K34: =IFERROR(J34*Продукт!B7,"")
A35: 27 | H35: =IF(F35="","",F35*(1+IFERROR(G35,0))) | J35: =IFERROR(H35*I35,"") | K35: =IFERROR(J35*Продукт!B7,"")
A37: ИТОГО ПО КАТЕГОРИИ: | J37: =SUMIF(J5:J35,">0") -> 0 | K37: =SUMIF(K5:K35,">0") -> 0

Sheet Б1 Оборудование
A1: 🟠 Б1. ОБОРУДОВАНИЕ (АМОРТИЗАЦИЯ) (норма на период)
A2: Амортизация: Цена / Срок службы (в мес) × Период. На 1 ед. = Амортизация / Объём выпуска.
A4: № | B4: Подкатегория / группа | C4: Наименование позиции | D4: Артикул / код | E4: Ед. изм. | F4: Расход за период | G4: Срок службы / интервал замены | H4: Ед. срока службы | I4: Цена за единицу | J4: Стоимость за период | K4: Стоимость на 1 ед. продукции | L4: Поставщик | M4: Дата последнего обновления | N4: Примечание
A5: Основное технологическое оборудование
A6: 1 | B6: Основное технологическое оборудование | C6: Литейная машина (ТПА) | E6: шт | H6: мес | J6: =IFERROR(F6*I6/G6*Продукт!B9,"") | K6: =IFERROR(J6/Продукт!B7,"")
A7: 2 | B7: Основное технологическое оборудование | C7: Экструдер | E7: шт | H7: мес | J7: =IFERROR(F7*I7/G7*Продукт!B9,"") | K7: =IFERROR(J7/Продукт!B7,"")
A8: 3 | B8: Основное технологическое оборудование | C8: Сборочная линия | E8: шт | H8: мес | J8: =IFERROR(F8*I8/G8*Продукт!B9,"") | K8: =IFERROR(J8/Продукт!B7,"")
A9: 4 | B9: Основное технологическое оборудование | C9: Подшипник | E9: шт | F9: 10 | G9: 6 | H9: мес | I9: 500000 | J9: =IFERROR(F9*I9/G9*Продукт!B9,"") -> 833333.33 | K9: =IFERROR(J9/Продукт!B7,"") -> 8.3333333
A10: 5 | B10: Основное технологическое оборудование | J10: =IFERROR(F10*I10/G10*Продукт!B9,"") | K10: =IFERROR(J10/Продукт!B7,"")
A11: 6 | B11: Основное технологическое оборудование | J11: =IFERROR(F11*I11/G11*Продукт!B9,"") | K11: =IFERROR(J11/Продукт!B7,"")
A12: 7 | B12: Основное технологическое оборудование | J12: =IFERROR(F12*I12/G12*Продукт!B9,"") | K12: =IFERROR(J12/Продукт!B7,"")
A13: 8 | B13: Основное технологическое оборудование | J13: =IFERROR(F13*I13/G13*Продукт!B9,"") | K13: =IFERROR(J13/Продукт!B7,"")
A14: Вспомогательное оборудование
A15: 9 | B15: Вспомогательное оборудование | C15: Компрессор | E15: шт | H15: мес | J15: =IFERROR(F15*I15/G15*Продукт!B9,"") | K15: =IFERROR(J15/Продукт!B7,"")
A16: 10 | B16: Вспомогательное оборудование | C16: Чиллер / охладитель | E16: шт | H16: мес | J16: =IFERROR(F16*I16/G16*Продукт!B9,"") | K16: =IFERROR(J16/Продукт!B7,"")
A17: 11 | B17: Вспомогательное оборудование | J17: =IFERROR(F17*I17/G17*Продукт!B9,"") | K17: =IFERROR(J17/Продукт!B7,"")
A18: 12 | B18: Вспомогательное оборудование | J18: =IFERROR(F18*I18/G18*Продукт!B9,"") | K18: =IFERROR(J18/Продукт!B7,"")
A19: 13 | B19: Вспомогательное оборудование | J19: =IFERROR(F19*I19/G19*Продукт!B9,"") | K19: =IFERROR(J19/Продукт!B7,"")
A20: 14 | B20: Вспомогательное оборудование | J20: =IFERROR(F20*I20/G20*Продукт!B9,"") | K20: =IFERROR(J20/Продукт!B7,"")
A21: 15 | B21: Вспомогательное оборудование | J21: =IFERROR(F21*I21/G21*Продукт!B9,"") | K21: =IFERROR(J21/Продукт!B7,"")
A22: Транспортное и складское оборудование
A23: 16 | B23: Транспортное и складское оборудование | C23: Конвейер | E23: шт | H23: мес | J23: =IFERROR(F23*I23/G23*Продукт!B9,"") | K23: =IFERROR(J23/Продукт!B7,"")
A24: 17 | B24: Транспортное и складское оборудование | C24: Погрузчик / штабелёр | E24: шт | H24: мес | J24: =IFERROR(F24*I24/G24*Продукт!B9,"") | K24: =IFERROR(J24/Продукт!B7,"")
A25: 18 | B25: Транспортное и складское оборудование | J25: =IFERROR(F25*I25/G25*Продукт!B9,"") | K25: =IFERROR(J25/Продукт!B7,"")
A26: 19 | B26: Транспортное и складское оборудование | J26: =IFERROR(F26*I26/G26*Продукт!B9,"") | K26: =IFERROR(J26/Продукт!B7,"")
A27: 20 | B27: Транспортное и складское оборудование | J27: =IFERROR(F27*I27/G27*Продукт!B9,"") | K27: =IFERROR(J27/Продукт!B7,"")
A28: 21 | B28: Транспортное и складское оборудование | J28: =IFERROR(F28*I28/G28*Продукт!B9,"") | K28: =IFERROR(J28/Продукт!B7,"")
A29: 22 | B29: Транспортное и складское оборудование | J29: =IFERROR(F29*I29/G29*Продукт!B9,"") | K29: =IFERROR(J29/Продукт!B7,"")
A30: + ДОБАВИТЬ ЕЩЁ ПУНКТ
A31: 23 | J31: =IFERROR(F31*I31/G31*Продукт!B9,"") | K31: =IFERROR(J31/Продукт!B7,"")
A32: 24 | J32: =IFERROR(F32*I32/G32*Продукт!B9,"") | K32: =IFERROR(J32/Продукт!B7,"")
A33: 25 | J33: =IFERROR(F33*I33/G33*Продукт!B9,"") | K33: =IFERROR(J33/Продукт!B7,"")
A34: 26 | J34: =IFERROR(F34*I34/G34*Продукт!B9,"") | K34: =IFERROR(J34/Продукт!B7,"")
A35: 27 | J35: =IFERROR(F35*I35/G35*Продукт!B9,"") | K35: =IFERROR(J35/Продукт!B7,"")
A37: ИТОГО ПО КАТЕГОРИИ: | J37: =SUMIF(J5:J35,">0") -> 833333.33 | K37: =SUMIF(K5:K35,">0") -> 8.3333333

Sheet Б2 Оснастка
A1: 🟠 Б2. ОСНАСТКА И ИНСТРУМЕНТ (ИЗНОС ПО ЦИКЛАМ) (норма на период)
A2: Износ по циклам: Цена / Срок службы (в циклах) = стоимость на 1 ед. продукции.
A4: № | B4: Подкатегория / группа | C4: Наименование позиции | D4: Артикул / код | E4: Ед. изм. | F4: Расход за период | G4: Срок службы / интервал замены | H4: Ед. срока службы | I4: Цена за единицу | J4: Стоимость за период | K4: Стоимость на 1 ед. продукции | L4: Поставщик | M4: Дата последнего обновления | N4: Примечание
A5: Формообразующая оснастка
A6: 1 | B6: Формообразующая оснастка | C6: Пресс-форма | E6: шт | H6: циклов | J6: =IFERROR(K6*Продукт!B7,"") | K6: =IFERROR(F6*I6/G6,"")
A7: 2 | B7: Формообразующая оснастка | C7: Штамп | E7: шт | H7: циклов | J7: =IFERROR(K7*Продукт!B7,"") | K7: =IFERROR(F7*I7/G7,"")
A8: 3 | B8: Формообразующая оснастка | C8: Матрица / пуансон | E8: шт | H8: циклов | J8: =IFERROR(K8*Продукт!B7,"") | K8: =IFERROR(F8*I8/G8,"")
A9: 4 | B9: Формообразующая оснастка | J9: =IFERROR(K9*Продукт!B7,"") | K9: =IFERROR(F9*I9/G9,"")
A10: 5 | B10: Формообразующая оснастка | J10: =IFERROR(K10*Продукт!B7,"") | K10: =IFERROR(F10*I10/G10,"")
A11: 6 | B11: Формообразующая оснастка | J11: =IFERROR(K11*Продукт!B7,"") | K11: =IFERROR(F11*I11/G11,"")
A12: 7 | B12: Формообразующая оснастка | J12: =IFERROR(K12*Продукт!B7,"") | K12: =IFERROR(F12*I12/G12,"")
A13: 8 | B13: Формообразующая оснастка | J13: =IFERROR(K13*Продукт!B7,"") | K13: =IFERROR(F13*I13/G13,"")
A14: Режущий и обрабатывающий инструмент
A15: 9 | B15: Режущий и обрабатывающий инструмент | C15: Фреза | E15: шт | H15: циклов | J15: =IFERROR(K15*Продукт!B7,"") | K15: =IFERROR(F15*I15/G15,"")
A16: 10 | B16: Режущий и обрабатывающий инструмент | C16: Резец | E16: шт | H16: циклов | J16: =IFERROR(K16*Продукт!B7,"") | K16: =IFERROR(F16*I16/G16,"")
A17: 11 | B17: Режущий и обрабатывающий инструмент | C17: Сверло | E17: шт | H17: циклов | J17: =IFERROR(K17*Продукт!B7,"") | K17: =IFERROR(F17*I17/G17,"")
A18: 12 | B18: Режущий и обрабатывающий инструмент | J18: =IFERROR(K18*Продукт!B7,"") | K18: =IFERROR(F18*I18/G18,"")
A19: 13 | B19: Режущий и обрабатывающий инструмент | J19: =IFERROR(K19*Продукт!B7,"") | K19: =IFERROR(F19*I19/G19,"")
A20: 14 | B20: Режущий и обрабатывающий инструмент | J20: =IFERROR(K20*Продукт!B7,"") | K20: =IFERROR(F20*I20/G20,"")
A21: 15 | B21: Режущий и обрабатывающий инструмент | J21: =IFERROR(K21*Продукт!B7,"") | K21: =IFERROR(F21*I21/G21,"")
A22: 16 | B22: Режущий и обрабатывающий инструмент | J22: =IFERROR(K22*Продукт!B7,"") | K22: =IFERROR(F22*I22/G22,"")
A23: Контрольно-измерительный инструмент
A24: 17 | B24: Контрольно-измерительный инструмент | C24: Калибр / шаблон | E24: шт | H24: циклов | J24: =IFERROR(K24*Продукт!B7,"") | K24: =IFERROR(F24*I24/G24,"")
A25: 18 | B25: Контрольно-измерительный инструмент | J25: =IFERROR(K25*Продукт!B7,"") | K25: =IFERROR(F25*I25/G25,"")
A26: 19 | B26: Контрольно-измерительный инструмент | J26: =IFERROR(K26*Продукт!B7,"") | K26: =IFERROR(F26*I26/G26,"")
A27: 20 | B27: Контрольно-измерительный инструмент | J27: =IFERROR(K27*Продукт!B7,"") | K27: =IFERROR(F27*I27/G27,"")
A28: 21 | B28: Контрольно-измерительный инструмент | J28: =IFERROR(K28*Продукт!B7,"") | K28: =IFERROR(F28*I28/G28,"")
A29: 22 | B29: Контрольно-измерительный инструмент | J29: =IFERROR(K29*Продукт!B7,"") | K29: =IFERROR(F29*I29/G29,"")
A30: + ДОБАВИТЬ ЕЩЁ ПУНКТ
A31: 23 | J31: =IFERROR(K31*Продукт!B7,"") | K31: =IFERROR(F31*I31/G31,"")
A32: 24 | J32: =IFERROR(K32*Продукт!B7,"") | K32: =IFERROR(F32*I32/G32,"")
A33: 25 | J33: =IFERROR(K33*Продукт!B7,"") | K33: =IFERROR(F33*I33/G33,"")
A34: 26 | J34: =IFERROR(K34*Продукт!B7,"") | K34: =IFERROR(F34*I34/G34,"")
A35: 27 | J35: =IFERROR(K35*Продукт!B7,"") | K35: =IFERROR(F35*I35/G35,"")
A37: ИТОГО ПО КАТЕГОРИИ: | J37: =SUMIF(J5:J35,">0") -> 0 | K37: =SUMIF(K5:K35,">0") -> 0

Sheet Б3 Запчасти
A1: 🟠 Б3. ЗАПАСНЫЕ ЧАСТИ (ПО ИНТЕРВАЛАМ ТО) (норма на период)
A2: Расход × Цена = Стоимость за период. На 1 ед. продукции = Стоимость / Объём выпуска.
A4: № | B4: Подкатегория / группа | C4: Наименование позиции | D4: Артикул / код | E4: Ед. изм. | F4: Расход за период | G4: Срок службы / интервал замены | H4: Ед. срока службы | I4: Цена за единицу | J4: Стоимость за период | K4: Стоимость на 1 ед. продукции | L4: Поставщик | M4: Дата последнего обновления | N4: Примечание
A5: Механические запчасти
A6: 1 | B6: Механические запчасти | C6: Подшипник | E6: шт | H6: мес | J6: =IFERROR(F6*I6,"") -> 0 | K6: =IFERROR(J6/Продукт!B7,"") -> 0
A7: 2 | B7: Механические запчасти | C7: Ремень приводной | E7: шт | H7: мес | J7: =IFERROR(F7*I7,"") -> 0 | K7: =IFERROR(J7/Продукт!B7,"") -> 0
A8: 3 | B8: Механические запчасти | C8: Шестерня | E8: шт | H8: мес | J8: =IFERROR(F8*I8,"") -> 0 | K8: =IFERROR(J8/Продукт!B7,"") -> 0
A9: 4 | B9: Механические запчасти | J9: =IFERROR(F9*I9,"") -> 0 | K9: =IFERROR(J9/Продукт!B7,"") -> 0
A10: 5 | B10: Механические запчасти | J10: =IFERROR(F10*I10,"") -> 0 | K10: =IFERROR(J10/Продукт!B7,"") -> 0
A11: 6 | B11: Механические запчасти | J11: =IFERROR(F11*I11,"") -> 0 | K11: =IFERROR(J11/Продукт!B7,"") -> 0
A12: 7 | B12: Механические запчасти | J12: =IFERROR(F12*I12,"") -> 0 | K12: =IFERROR(J12/Продукт!B7,"") -> 0
A13: 8 | B13: Механические запчасти | J13: =IFERROR(F13*I13,"") -> 0 | K13: =IFERROR(J13/Продукт!B7,"") -> 0
A14: Электрические запчасти
A15: 9 | B15: Электрические запчасти | C15: Нагревательный элемент (ТЭН) | E15: шт | H15: мес | J15: =IFERROR(F15*I15,"") -> 0 | K15: =IFERROR(J15/Продукт!B7,"") -> 0
A16: 10 | B16: Электрические запчасти | C16: Датчик температуры | E16: шт | H16: мес | J16: =IFERROR(F16*I16,"") -> 0 | K16: =IFERROR(J16/Продукт!B7,"") -> 0
A17: 11 | B17: Электрические запчасти | C17: Реле / контактор | E17: шт | H17: мес | J17: =IFERROR(F17*I17,"") -> 0 | K17: =IFERROR(J17/Продукт!B7,"") -> 0
A18: 12 | B18: Электрические запчасти | J18: =IFERROR(F18*I18,"") -> 0 | K18: =IFERROR(J18/Продукт!B7,"") -> 0
A19: 13 | B19: Электрические запчасти | J19: =IFERROR(F19*I19,"") -> 0 | K19: =IFERROR(J19/Продукт!B7,"") -> 0
A20: 14 | B20: Электрические запчасти | J20: =IFERROR(F20*I20,"") -> 0 | K20: =IFERROR(J20/Продукт!B7,"") -> 0
A21: 15 | B21: Электрические запчасти | J21: =IFERROR(F21*I21,"") -> 0 | K21: =IFERROR(J21/Продукт!B7,"") -> 0
A22: 16 | B22: Электрические запчасти | J22: =IFERROR(F22*I22,"") -> 0 | K22: =IFERROR(J22/Продукт!B7,"") -> 0
A23: Пневматика и гидравлика
A24: 17 | B24: Пневматика и гидравлика | C24: Пневмоцилиндр | E24: шт | H24: мес | J24: =IFERROR(F24*I24,"") -> 0 | K24: =IFERROR(J24/Продукт!B7,"") -> 0
A25: 18 | B25: Пневматика и гидравлика | C25: Уплотнение / сальник | E25: шт | H25: мес | J25: =IFERROR(F25*I25,"") -> 0 | K25: =IFERROR(J25/Продукт!B7,"") -> 0
A26: 19 | B26: Пневматика и гидравлика | J26: =IFERROR(F26*I26,"") -> 0 | K26: =IFERROR(J26/Продукт!B7,"") -> 0
A27: 20 | B27: Пневматика и гидравлика | J27: =IFERROR(F27*I27,"") -> 0 | K27: =IFERROR(J27/Продукт!B7,"") -> 0
A28: 21 | B28: Пневматика и гидравлика | J28: =IFERROR(F28*I28,"") -> 0 | K28: =IFERROR(J28/Продукт!B7,"") -> 0
A29: 22 | B29: Пневматика и гидравлика | J29: =IFERROR(F29*I29,"") -> 0 | K29: =IFERROR(J29/Продукт!B7,"") -> 0
A30: 23 | B30: Пневматика и гидравлика | J30: =IFERROR(F30*I30,"") -> 0 | K30: =IFERROR(J30/Продукт!B7,"") -> 0
A31: + ДОБАВИТЬ ЕЩЁ ПУНКТ
A32: 24 | J32: =IFERROR(F32*I32,"") -> 0 | K32: =IFERROR(J32/Продукт!B7,"") -> 0
A33: 25 | J33: =IFERROR(F33*I33,"") -> 0 | K33: =IFERROR(J33/Продукт!B7,"") -> 0
A34: 26 | J34: =IFERROR(F34*I34,"") -> 0 | K34: =IFERROR(J34/Продукт!B7,"") -> 0
A35: 27 | J35: =IFERROR(F35*I35,"") -> 0 | K35: =IFERROR(J35/Продукт!B7,"") -> 0
A36: 28 | J36: =IFERROR(F36*I36,"") -> 0 | K36: =IFERROR(J36/Продукт!B7,"") -> 0
A38: ИТОГО ПО КАТЕГОРИИ: | J38: =SUMIF(J5:J36,">0") -> 0 | K38: =SUMIF(K5:K36,">0") -> 0

Sheet Б4 Расходники
A1: 🟠 Б4. РАСХОДНИКИ ОБОРУДОВАНИЯ (норма на период)
A2: Расход × Цена = Стоимость за период. На 1 ед. продукции = Стоимость / Объём выпуска.
A4: № | B4: Подкатегория / группа | C4: Наименование позиции | D4: Артикул / код | E4: Ед. изм. | F4: Расход за период | G4: Срок службы / интервал замены | H4: Ед. срока службы | I4: Цена за единицу | J4: Стоимость за период | K4: Стоимость на 1 ед. продукции | L4: Поставщик | M4: Дата последнего обновления | N4: Примечание
A5: Смазочные материалы
A6: 1 | B6: Смазочные материалы | C6: Масло индустриальное | E6: л | H6: мес | J6: =IFERROR(F6*I6,"") -> 0 | K6: =IFERROR(J6/Продукт!B7,"") -> 0
A7: 2 | B7: Смазочные материалы | C7: Смазка консистентная | E7: кг | H7: мес | J7: =IFERROR(F7*I7,"") -> 0 | K7: =IFERROR(J7/Продукт!B7,"") -> 0
A8: 3 | B8: Смазочные материалы | J8: =IFERROR(F8*I8,"") -> 0 | K8: =IFERROR(J8/Продукт!B7,"") -> 0
A9: 4 | B9: Смазочные материалы | J9: =IFERROR(F9*I9,"") -> 0 | K9: =IFERROR(J9/Продукт!B7,"") -> 0
A10: 5 | B10: Смазочные материалы | J10: =IFERROR(F10*I10,"") -> 0 | K10: =IFERROR(J10/Продукт!B7,"") -> 0
A11: 6 | B11: Смазочные материалы | J11: =IFERROR(F11*I11,"") -> 0 | K11: =IFERROR(J11/Продукт!B7,"") -> 0
A12: 7 | B12: Смазочные материалы | J12: =IFERROR(F12*I12,"") -> 0 | K12: =IFERROR(J12/Продукт!B7,"") -> 0
A13: Технические жидкости
A14: 8 | B14: Технические жидкости | C14: СОЖ (смазочно-охлаждающая) | E14: л | H14: мес | J14: =IFERROR(F14*I14,"") -> 0 | K14: =IFERROR(J14/Продукт!B7,"") -> 0
A15: 9 | B15: Технические жидкости | C15: Гидравлическая жидкость | E15: л | H15: мес | J15: =IFERROR(F15*I15,"") -> 0 | K15: =IFERROR(J15/Продукт!B7,"") -> 0
A16: 10 | B16: Технические жидкости | J16: =IFERROR(F16*I16,"") -> 0 | K16: =IFERROR(J16/Продукт!B7,"") -> 0
A17: 11 | B17: Технические жидкости | J17: =IFERROR(F17*I17,"") -> 0 | K17: =IFERROR(J17/Продукт!B7,"") -> 0
A18: 12 | B18: Технические жидкости | J18: =IFERROR(F18*I18,"") -> 0 | K18: =IFERROR(J18/Продукт!B7,"") -> 0
A19: 13 | B19: Технические жидкости | J19: =IFERROR(F19*I19,"") -> 0 | K19: =IFERROR(J19/Продукт!B7,"") -> 0
A20: 14 | B20: Технические жидкости | J20: =IFERROR(F20*I20,"") -> 0 | K20: =IFERROR(J20/Продукт!B7,"") -> 0
A21: Фильтры и очистка
A22: 15 | B22: Фильтры и очистка | C22: Фильтр воздушный | E22: шт | H22: мес | J22: =IFERROR(F22*I22,"") -> 0 | K22: =IFERROR(J22/Продукт!B7,"") -> 0
A23: 16 | B23: Фильтры и очистка | C23: Фильтр масляный | E23: шт | H23: мес | J23: =IFERROR(F23*I23,"") -> 0 | K23: =IFERROR(J23/Продукт!B7,"") -> 0
A24: 17 | B24: Фильтры и очистка | C24: Ветошь, салфетки технические | E24: кг | H24: мес | J24: =IFERROR(F24*I24,"") -> 0 | K24: =IFERROR(J24/Продукт!B7,"") -> 0
A25: 18 | B25: Фильтры и очистка | J25: =IFERROR(F25*I25,"") -> 0 | K25: =IFERROR(J25/Продукт!B7,"") -> 0
A26: 19 | B26: Фильтры и очистка | J26: =IFERROR(F26*I26,"") -> 0 | K26: =IFERROR(J26/Продукт!B7,"") -> 0
A27: 20 | B27: Фильтры и очистка | J27: =IFERROR(F27*I27,"") -> 0 | K27: =IFERROR(J27/Продукт!B7,"") -> 0
A28: 21 | B28: Фильтры и очистка | J28: =IFERROR(F28*I28,"") -> 0 | K28: =IFERROR(J28/Продукт!B7,"") -> 0
A29: 22 | B29: Фильтры и очистка | J29: =IFERROR(F29*I29,"") -> 0 | K29: =IFERROR(J29/Продукт!B7,"") -> 0
A30: + ДОБАВИТЬ ЕЩЁ ПУНКТ
A31: 23 | J31: =IFERROR(F31*I31,"") -> 0 | K31: =IFERROR(J31/Продукт!B7,"") -> 0
A32: 24 | J32: =IFERROR(F32*I32,"") -> 0 | K32: =IFERROR(J32/Продукт!B7,"") -> 0
A33: 25 | J33: =IFERROR(F33*I33,"") -> 0 | K33: =IFERROR(J33/Продукт!B7,"") -> 0
A34: 26 | J34: =IFERROR(F34*I34,"") -> 0 | K34: =IFERROR(J34/Продукт!B7,"") -> 0
A35: 27 | J35: =IFERROR(F35*I35,"") -> 0 | K35: =IFERROR(J35/Продукт!B7,"") -> 0
A37: ИТОГО ПО КАТЕГОРИИ: | J37: =SUMIF(J5:J35,">0") -> 0 | K37: =SUMIF(K5:K35,">0") -> 0

Sheet Б5 Материалы ТОиР
A1: 🟠 Б5. МАТЕРИАЛЫ ДЛЯ ТОИР (норма на период)
A2: Расход × Цена = Стоимость за период. На 1 ед. продукции = Стоимость / Объём выпуска.
A4: № | B4: Подкатегория / группа | C4: Наименование позиции | D4: Артикул / код | E4: Ед. изм. | F4: Расход за период | G4: Срок службы / интервал замены | H4: Ед. срока службы | I4: Цена за единицу | J4: Стоимость за период | K4: Стоимость на 1 ед. продукции | L4: Поставщик | M4: Дата последнего обновления | N4: Примечание
A5: Уплотнители и герметики
A6: 1 | B6: Уплотнители и герметики | C6: Прокладки, сальники | E6: шт | H6: мес | J6: =IFERROR(F6*I6,"") -> 0 | K6: =IFERROR(J6/Продукт!B7,"") -> 0
A7: 2 | B7: Уплотнители и герметики | C7: Герметик силиконовый | E7: тюбик | H7: мес | J7: =IFERROR(F7*I7,"") -> 0 | K7: =IFERROR(J7/Продукт!B7,"") -> 0
A8: 3 | B8: Уплотнители и герметики | C8: Фум-лента | E8: м | H8: мес | J8: =IFERROR(F8*I8,"") -> 0 | K8: =IFERROR(J8/Продукт!B7,"") -> 0
A9: 4 | B9: Уплотнители и герметики | J9: =IFERROR(F9*I9,"") -> 0 | K9: =IFERROR(J9/Продукт!B7,"") -> 0
A10: 5 | B10: Уплотнители и герметики | J10: =IFERROR(F10*I10,"") -> 0 | K10: =IFERROR(J10/Продукт!B7,"") -> 0
A11: 6 | B11: Уплотнители и герметики | J11: =IFERROR(F11*I11,"") -> 0 | K11: =IFERROR(J11/Продукт!B7,"") -> 0
A12: 7 | B12: Уплотнители и герметики | J12: =IFERROR(F12*I12,"") -> 0 | K12: =IFERROR(J12/Продукт!B7,"") -> 0
A13: 8 | B13: Уплотнители и герметики | J13: =IFERROR(F13*I13,"") -> 0 | K13: =IFERROR(J13/Продукт!B7,"") -> 0
A14: Метизы для ремонта
A15: 9 | B15: Метизы для ремонта | C15: Болты, гайки, шайбы (комплект) | E15: компл | H15: мес | J15: =IFERROR(F15*I15,"") -> 0 | K15: =IFERROR(J15/Продукт!B7,"") -> 0
A16: 10 | B16: Метизы для ремонта | J16: =IFERROR(F16*I16,"") -> 0 | K16: =IFERROR(J16/Продукт!B7,"") -> 0
A17: 11 | B17: Метизы для ремонта | J17: =IFERROR(F17*I17,"") -> 0 | K17: =IFERROR(J17/Продукт!B7,"") -> 0
A18: 12 | B18: Метизы для ремонта | J18: =IFERROR(F18*I18,"") -> 0 | K18: =IFERROR(J18/Продукт!B7,"") -> 0
A19: 13 | B19: Метизы для ремонта | J19: =IFERROR(F19*I19,"") -> 0 | K19: =IFERROR(J19/Продукт!B7,"") -> 0
A20: 14 | B20: Метизы для ремонта | J20: =IFERROR(F20*I20,"") -> 0 | K20: =IFERROR(J20/Продукт!B7,"") -> 0
A21: Краски и антикор
A22: 15 | B22: Краски и антикор | C22: Краска для оборудования | E22: л | H22: мес | J22: =IFERROR(F22*I22,"") -> 0 | K22: =IFERROR(J22/Продукт!B7,"") -> 0
A23: 16 | B23: Краски и антикор | C23: Грунтовка | E23: л | H23: мес | J23: =IFERROR(F23*I23,"") -> 0 | K23: =IFERROR(J23/Продукт!B7,"") -> 0
A24: 17 | B24: Краски и антикор | J24: =IFERROR(F24*I24,"") -> 0 | K24: =IFERROR(J24/Продукт!B7,"") -> 0
A25: 18 | B25: Краски и антикор | J25: =IFERROR(F25*I25,"") -> 0 | K25: =IFERROR(J25/Продукт!B7,"") -> 0
A26: 19 | B26: Краски и антикор | J26: =IFERROR(F26*I26,"") -> 0 | K26: =IFERROR(J26/Продукт!B7,"") -> 0
A27: 20 | B27: Краски и антикор | J27: =IFERROR(F27*I27,"") -> 0 | K27: =IFERROR(J27/Продукт!B7,"") -> 0
A28: 21 | B28: Краски и антикор | J28: =IFERROR(F28*I28,"") -> 0 | K28: =IFERROR(J28/Продукт!B7,"") -> 0
A29: Электрика для ремонта
A30: 22 | B30: Электрика для ремонта | C30: Кабель / провод | E30: м | H30: мес | J30: =IFERROR(F30*I30,"") -> 0 | K30: =IFERROR(J30/Продукт!B7,"") -> 0
A31: 23 | B31: Электрика для ремонта | C31: Изолента, термоусадка | E31: шт | H31: мес | J31: =IFERROR(F31*I31,"") -> 0 | K31: =IFERROR(J31/Продукт!B7,"") -> 0
A32: 24 | B32: Электрика для ремонта | C32: Лампы освещения | E32: шт | H32: мес | J32: =IFERROR(F32*I32,"") -> 0 | K32: =IFERROR(J32/Продукт!B7,"") -> 0
A33: 25 | B33: Электрика для ремонта | J33: =IFERROR(F33*I33,"") -> 0 | K33: =IFERROR(J33/Продукт!B7,"") -> 0
A34: 26 | B34: Электрика для ремонта | J34: =IFERROR(F34*I34,"") -> 0 | K34: =IFERROR(J34/Продукт!B7,"") -> 0
A35: 27 | B35: Электрика для ремонта | J35: =IFERROR(F35*I35,"") -> 0 | K35: =IFERROR(J35/Продукт!B7,"") -> 0
A36: 28 | B36: Электрика для ремонта | J36: =IFERROR(F36*I36,"") -> 0 | K36: =IFERROR(J36/Продукт!B7,"") -> 0
A37: 29 | B37: Электрика для ремонта | J37: =IFERROR(F37*I37,"") -> 0 | K37: =IFERROR(J37/Продукт!B7,"") -> 0
A38: Сварка и абразивы
A39: 30 | B39: Сварка и абразивы | C39: Сварочные электроды | E39: кг | H39: мес | J39: =IFERROR(F39*I39,"") -> 0 | K39: =IFERROR(J39/Продукт!B7,"") -> 0
A40: 31 | B40: Сварка и абразивы | C40: Шлифовальные круги | E40: шт | H40: мес | J40: =IFERROR(F40*I40,"") -> 0 | K40: =IFERROR(J40/Продукт!B7,"") -> 0
A41: 32 | B41: Сварка и абразивы | J41: =IFERROR(F41*I41,"") -> 0 | K41: =IFERROR(J41/Продукт!B7,"") -> 0
...

Sheet Б6 СИЗ и санитария
A1: 🟠 Б6. СИЗ И САНИТАРИЯ (норма на период)
A2: Расход × Цена = Стоимость за период. На 1 ед. продукции = Стоимость / Объём выпуска.
A4: № | B4: Подкатегория / группа | C4: Наименование позиции | D4: Артикул / код | E4: Ед. изм. | F4: Расход за период | G4: Срок службы / интервал замены | H4: Ед. срока службы | I4: Цена за единицу | J4: Стоимость за период | K4: Стоимость на 1 ед. продукции | L4: Поставщик | M4: Дата последнего обновления | N4: Примечание
A5: Средства индивидуальной защиты
A6: 1 | B6: Средства индивидуальной защиты | C6: Перчатки | E6: пара | H6: мес | J6: =IFERROR(F6*I6,"") -> 0 | K6: =IFERROR(J6/Продукт!B7,"") -> 0
A7: 2 | B7: Средства индивидуальной защиты | C7: Маска / респиратор | E7: шт | H7: мес | J7: =IFERROR(F7*I7,"") -> 0 | K7: =IFERROR(J7/Продукт!B7,"") -> 0
A8: 3 | B8: Средства индивидуальной защиты | C8: Защитные очки | E8: шт | H8: мес | J8: =IFERROR(F8*I8,"") -> 0 | K8: =IFERROR(J8/Продукт!B7,"") -> 0
A9: 4 | B9: Средства индивидуальной защиты | C9: Бахилы | E9: пара | H9: мес | J9: =IFERROR(F9*I9,"") -> 0 | K9: =IFERROR(J9/Продукт!B7,"") -> 0
A10: 5 | B10: Средства индивидуальной защиты | J10: =IFERROR(F10*I10,"") -> 0 | K10: =IFERROR(J10/Продукт!B7,"") -> 0
A11: 6 | B11: Средства индивидуальной защиты | J11: =IFERROR(F11*I11,"") -> 0 | K11: =IFERROR(J11/Продукт!B7,"") -> 0
A12: 7 | B12: Средства индивидуальной защиты | J12: =IFERROR(F12*I12,"") -> 0 | K12: =IFERROR(J12/Продукт!B7,"") -> 0
A13: 8 | B13: Средства индивидуальной защиты | J13: =IFERROR(F13*I13,"") -> 0 | K13: =IFERROR(J13/Продукт!B7,"") -> 0
A14: 9 | B14: Средства индивидуальной защиты | J14: =IFERROR(F14*I14,"") -> 0 | K14: =IFERROR(J14/Продукт!B7,"") -> 0
A15: Спецодежда
A16: 10 | B16: Спецодежда | C16: Халат / комбинезон | E16: шт | H16: мес | J16: =IFERROR(F16*I16,"") -> 0 | K16: =IFERROR(J16/Продукт!B7,"") -> 0
A17: 11 | B17: Спецодежда | C17: Обувь рабочая | E17: пара | H17: мес | J17: =IFERROR(F17*I17,"") -> 0 | K17: =IFERROR(J17/Продукт!B7,"") -> 0
A18: 12 | B18: Спецодежда | C18: Шапочка / косынка | E18: шт | H18: мес | J18: =IFERROR(F18*I18,"") -> 0 | K18: =IFERROR(J18/Продукт!B7,"") -> 0
A19: 13 | B19: Спецодежда | J19: =IFERROR(F19*I19,"") -> 0 | K19: =IFERROR(J19/Продукт!B7,"") -> 0
A20: 14 | B20: Спецодежда | J20: =IFERROR(F20*I20,"") -> 0 | K20: =IFERROR(J20/Продукт!B7,"") -> 0
A21: 15 | B21: Спецодежда | J21: =IFERROR(F21*I21,"") -> 0 | K21: =IFERROR(J21/Продукт!B7,"") -> 0
A22: 16 | B22: Спецодежда | J22: =IFERROR(F22*I22,"") -> 0 | K22: =IFERROR(J22/Продукт!B7,"") -> 0
A23: 17 | B23: Спецодежда | J23: =IFERROR(F23*I23,"") -> 0 | K23: =IFERROR(J23/Продукт!B7,"") -> 0
A24: Уборка и дезинфекция
A25: 18 | B25: Уборка и дезинфекция | C25: Моющее средство | E25: л | H25: мес | J25: =IFERROR(F25*I25,"") -> 0 | K25: =IFERROR(J25/Продукт!B7,"") -> 0
A26: 19 | B26: Уборка и дезинфекция | C26: Дезинфицирующее средство | E26: л | H26: мес | J26: =IFERROR(F26*I26,"") -> 0 | K26: =IFERROR(J26/Продукт!B7,"") -> 0
A27: 20 | B27: Уборка и дезинфекция | C27: Тряпки / мопы | E27: шт | H27: мес | J27: =IFERROR(F27*I27,"") -> 0 | K27: =IFERROR(J27/Продукт!B7,"") -> 0
A28: 21 | B28: Уборка и дезинфекция | J28: =IFERROR(F28*I28,"") -> 0 | K28: =IFERROR(J28/Продукт!B7,"") -> 0
A29: 22 | B29: Уборка и дезинфекция | J29: =IFERROR(F29*I29,"") -> 0 | K29: =IFERROR(J29/Продукт!B7,"") -> 0
A30: 23 | B30: Уборка и дезинфекция | J30: =IFERROR(F30*I30,"") -> 0 | K30: =IFERROR(J30/Продукт!B7,"") -> 0
A31: 24 | B31: Уборка и дезинфекция | J31: =IFERROR(F31*I31,"") -> 0 | K31: =IFERROR(J31/Продукт!B7,"") -> 0
A32: 25 | B32: Уборка и дезинфекция | J32: =IFERROR(F32*I32,"") -> 0 | K32: =IFERROR(J32/Продукт!B7,"") -> 0
A33: + ДОБАВИТЬ ЕЩЁ ПУНКТ
A34: 26 | J34: =IFERROR(F34*I34,"") -> 0 | K34: =IFERROR(J34/Продукт!B7,"") -> 0
A35: 27 | J35: =IFERROR(F35*I35,"") -> 0 | K35: =IFERROR(J35/Продукт!B7,"") -> 0
A36: 28 | J36: =IFERROR(F36*I36,"") -> 0 | K36: =IFERROR(J36/Продукт!B7,"") -> 0
A37: 29 | J37: =IFERROR(F37*I37,"") -> 0 | K37: =IFERROR(J37/Продукт!B7,"") -> 0
A38: 30 | J38: =IFERROR(F38*I38,"") -> 0 | K38: =IFERROR(J38/Продукт!B7,"") -> 0
A40: ИТОГО ПО КАТЕГОРИИ: | J40: =SUMIF(J5:J38,">0") -> 0 | K40: =SUMIF(K5:K38,">0") -> 0

Sheet Б7 Услуги
A1: 🟠 Б7. УСЛУГИ (АУТСОРС И ПОДРЯД) (норма на период)
A2: Расход × Цена = Стоимость за период. На 1 ед. продукции = Стоимость / Объём выпуска.
A4: № | B4: Подкатегория / группа | C4: Наименование позиции | D4: Артикул / код | E4: Ед. изм. | F4: Расход за период | G4: Срок службы / интервал замены | H4: Ед. срока службы | I4: Цена за единицу | J4: Стоимость за период | K4: Стоимость на 1 ед. продукции | L4: Поставщик | M4: Дата последнего обновления | N4: Примечание
A5: Логистика и транспорт
A6: 1 | B6: Логистика и транспорт | C6: Доставка сырья | E6: рейс | H6: мес | J6: =IFERROR(F6*I6,"") -> 0 | K6: =IFERROR(J6/Продукт!B7,"") -> 0
A7: 2 | B7: Логистика и транспорт | C7: Отгрузка готовой продукции | E7: рейс | H7: мес | J7: =IFERROR(F7*I7,"") -> 0 | K7: =IFERROR(J7/Продукт!B7,"") -> 0
A8: 3 | B8: Логистика и транспорт | C8: Таможенное оформление | E8: декл | H8: мес | J8: =IFERROR(F8*I8,"") -> 0 | K8: =IFERROR(J8/Продукт!B7,"") -> 0
A9: 4 | B9: Логистика и транспорт | J9: =IFERROR(F9*I9,"") -> 0 | K9: =IFERROR(J9/Продукт!B7,"") -> 0
A10: 5 | B10: Логистика и транспорт | J10: =IFERROR(F10*I10,"") -> 0 | K10: =IFERROR(J10/Продукт!B7,"") -> 0
A11: 6 | B11: Логистика и транспорт | J11: =IFERROR(F11*I11,"") -> 0 | K11: =IFERROR(J11/Продукт!B7,"") -> 0
A12: 7 | B12: Логистика и транспорт | J12: =IFERROR(F12*I12,"") -> 0 | K12: =IFERROR(J12/Продукт!B7,"") -> 0
A13: 8 | B13: Логистика и транспорт | J13: =IFERROR(F13*I13,"") -> 0 | K13: =IFERROR(J13/Продукт!B7,"") -> 0
A14: Сертификация и контроль
A15: 9 | B15: Сертификация и контроль | C15: Сертификация (ISO/ГОСТ) | E15: услуга | H15: год | J15: =IFERROR(F15*I15,"") -> 0 | K15: =IFERROR(J15/Продукт!B7,"") -> 0
A16: 10 | B16: Сертификация и контроль | C16: Лабораторные анализы | E16: анализ | H16: мес | J16: =IFERROR(F16*I16,"") -> 0 | K16: =IFERROR(J16/Продукт!B7,"") -> 0
A17: 11 | B17: Сертификация и контроль | C17: Поверка КИП | E17: прибор | H17: год | J17: =IFERROR(F17*I17,"") -> 0 | K17: =IFERROR(J17/Продукт!B7,"") -> 0
A18: 12 | B18: Сертификация и контроль | J18: =IFERROR(F18*I18,"") -> 0 | K18: =IFERROR(J18/Продукт!B7,"") -> 0
A19: 13 | B19: Сертификация и контроль | J19: =IFERROR(F19*I19,"") -> 0 | K19: =IFERROR(J19/Продукт!B7,"") -> 0
A20: 14 | B20: Сертификация и контроль | J20: =IFERROR(F20*I20,"") -> 0 | K20: =IFERROR(J20/Продукт!B7,"") -> 0
A21: 15 | B21: Сертификация и контроль | J21: =IFERROR(F21*I21,"") -> 0 | K21: =IFERROR(J21/Продукт!B7,"") -> 0
A22: 16 | B22: Сертификация и контроль | J22: =IFERROR(F22*I22,"") -> 0 | K22: =IFERROR(J22/Продукт!B7,"") -> 0
A23: Подрядные работы
