Workbook

Sheet Инструкция
A1: НОРМЫ РАСХОДОВ НА ПРОИЗВОДСТВО
A2: Универсальный шаблон для любого производства
A4: КАК ПОЛЬЗОВАТЬСЯ ШАБЛОНОМ
A6: 1. Заполните лист "Продукт" — укажите, что и в каком объёме вы производите.
A7: 2. Пройдите по листам категорий и заполните позиции, которые используете.
A8: 3. В каждой категории есть пустые строки и блок "ДОБАВИТЬ ЕЩЁ ПУНКТ" — дописывайте свои.
A9: 4. Колонка "Норма расхода на 1 ед. продукции" — главное поле для расчётов.
A10: 5. Стоимость рассчитывается автоматически по формуле: Норма × Цена × Объём выпуска.
A11: 6. Итоговая себестоимость собирается на листе "Сводка".
A13: ЦВЕТОВАЯ ЛЕГЕНДА:
B15: Заголовки таблиц
B16: Категория / группа
B17: Поле "ДОБАВИТЬ ЕЩЁ ПУНКТ"
B18: Итоговые строки
B19: Ключевые параметры — заполнить обязательно
A21: СТРУКТУРА ШАБЛОНА (категории)
A22: Лист | B22: Описание
A23: 1. Продукт | B23: Информация о производимом продукте и плановом объёме выпуска
A24: 2. Сырьё (основное) | B24: Материалы, из которых состоит готовая продукция
A25: 3. Вспом. материалы | B25: Добавки, красители, смазки, реагенты
A26: 4. Упаковка | B26: Тара, плёнка, этикетки, коробки, паллеты
A27: 5. Комплектующие | B27: Готовые детали и узлы, встраиваемые в продукт
A28: 6. Оборудование | B28: Основные средства: станки, линии, машины
A29: 7. Оснастка и инструмент | B29: Пресс-формы, штампы, матрицы, режущий инструмент
A30: 8. Запчасти (ЗИП) | B30: Запасные части для оборудования
A31: 9. Расходники оборудования | B31: Масла, смазки, фильтры, СОЖ
A32: 10. Энергоресурсы | B32: Электричество, вода, газ, пар, сжатый воздух
A33: 11. СИЗ и санитария | B33: Перчатки, маски, спецодежда, моющие средства
... A35: 13. Сводка | B35: Итоговая себестоимость по всем категориям

Sheet Продукт
A1: ИНФОРМАЦИЯ О ПРОДУКТЕ
A3: Параметр | B3: Значение | C3: Комментарий / пример
A4: Наименование продукта | B4: Шприц 10 мл | C4: Например: Шприц одноразовый 10мл / Стул деревянный / Хлеб ржаной
A5: Технические параметры | C5: Размер, Цвет, сорт ….
A6: Единица измерения готовой продукции | B6: литр | C6: шт, кг, л, м, упаковка
A7: Плановый объём выпуска за период | B7: 250000000 | C7: Используется для расчёта общих затрат
A8: Период (день/месяц/год) | B8: день
A9: Дата составления норм
A10: Ответственный (ФИО)

Sheet Лист1
B2: Общая норма расходов исходя из объема производства
E4: Общая норма на плановый объем продукции | F4: РАСЧЕТ ПОТРЕБНОСТИ НА 3 месяц | G4: Складской запас (ЕСТЬ) | J4: Потребность
A5: =Инструкция!$A$24 -> 2. Сырьё (основное) | B5: =Сырьё!C6 -> Полипропилен гранулированный | C5: =Сырьё!D6 -> J-560M | D5: =Сырьё!E6 -> кг | E5: =Сырьё!H6*Продукт!$B$7 -> 793905.45 | F5: =ROUND(E5/12*10,0) -> 661588 | G5: 400000 | J5: =IF((F5-G5)<=0,"ДОСТАТОЧНО",F5-G5) -> 261588
B6: =Сырьё!C7 -> Скользящая добавка Кродамид марки Crodamide OR BEAD | C6: =Сырьё!D7 -> 0 | D6: =Сырьё!E7 -> кг | E6: =Сырьё!H7*Продукт!$B$7 -> 2381.075 | F6: =ROUND(E6/12*10,0) -> 1984 | G6: 3000 | J6: =IF((F6-G6)<=0,"ДОСТАТОЧНО",F6-G6) -> ДОСТАТОЧНО
B7: =Сырьё!C8 -> Полиэтилен низкого давления марки I-1561 | C7: =Сырьё!D8 -> HDPE I-1561 | D7: =Сырьё!E8 -> кг | E7: =Сырьё!H8*Продукт!$B$7 -> 769322.05 | F7: =ROUND(E7/12*10,0) -> 641102 | G7: 505000 | J7: =IF((F7-G7)<=0,"ДОСТАТОЧНО",F7-G7) -> 136102
B8: =Сырьё!C9 -> Суперконцентрат на основе полиэтилена белый UN-0005 | C8: =Сырьё!D9 -> 0 | D8: =Сырьё!E9 -> кг | E8: =Сырьё!H9*Продукт!$B$7 -> 2307.85 | F8: =ROUND(E8/12*10,0) -> 1923 | G8: 5000 | J8: =IF((F8-G8)<=0,"ДОСТАТОЧНО",F8-G8) -> ДОСТАТОЧНО
B9: =Сырьё!C10 -> Спирт этиловый | C9: =Сырьё!D10 -> 0 | D9: =Сырьё!E10 -> л | E9: =Сырьё!H10*Продукт!$B$7 -> 300.475 | F9: =ROUND(E9/12*10,0) -> 250 | G9: 500 | J9: =IF((F9-G9)<=0,"ДОСТАТОЧНО",F9-G9) -> ДОСТАТОЧНО
A10: =Инструкция!$A$26 -> 4. Упаковка | B10: =Упаковка!C6 -> Упаковочный лист для ящиков | C10: =Упаковка!D6 -> 0 | D10: =Упаковка!E6 -> шт. | E10: =Упаковка!H6*Продукт!$B$7 -> 182150 | F10: =ROUND(E10/12*10,0) -> 151792 | G10: 150000 | J10: =IF((F10-G10)<=0,"ДОСТАТОЧНО",F10-G10) -> 1792
B11: =Упаковка!C7 -> Инструкция на шприцы | C11: =Упаковка!D7 -> 0 | D11: =Упаковка!E7 -> шт. | E11: =Упаковка!H7*Продукт!$B$7 -> 182150 | F11: =ROUND(E11/12*10,0) -> 151792 | G11: 150000 | J11: =IF((F11-G11)<=0,"ДОСТАТОЧНО",F11-G11) -> 1792
B12: =Упаковка!C8 -> Ящики упаковочные из гофрированного картона размерами 600*400*430 мм | C12: =Упаковка!D8 -> 0 | D12: =Упаковка!E8 -> шт. | E12: =Упаковка!H8*Продукт!$B$7 -> 179475 | F12: =ROUND(E12/12*10,0) -> 149563 | G12: 150000 | J12: =IF((F12-G12)<=0,"ДОСТАТОЧНО",F12-G12) -> ДОСТАТОЧНО
B13: =Упаковка!C9 -> Вкладыши для ящика, по 2шт. На ящик, размером 550*330мм | C13: =Упаковка!D9 -> 0 | D13: =Упаковка!E9 -> шт. | E13: =Упаковка!H9*Продукт!$B$7 -> 357250 | F13: =ROUND(E13/12*10,0) -> 297708 | G13: 150000 | J13: =IF((F13-G13)<=0,"ДОСТАТОЧНО",F13-G13) -> 147708
B14: =Упаковка!C10 -> Скобы для ящика размерами 15*35мм, по 2шт. На ящик | C14: =Упаковка!D10 -> 0 | D14: =Упаковка!E10 -> шт. | E14: =Упаковка!H10*Продукт!$B$7 -> 371500 | F14: =ROUND(E14/12*10,0) -> 309583 | G14: 150000 | J14: =IF((F14-G14)<=0,"ДОСТАТОЧНО",F14-G14) -> 159583
B15: =Упаковка!C11 -> Скотч лента, в рулонах, длиной 100м. | C15: =Упаковка!D11 -> 0 | D15: =Упаковка!E11 -> шт. | E15: =Упаковка!H11*Продукт!$B$7 -> 1485 | F15: =ROUND(E15/12*10,0) -> 1238 | G15: 150000 | J15: =IF((F15-G15)<=0,"ДОСТАТОЧНО",F15-G15) -> ДОСТАТОЧНО
B16: =Упаковка!C12 -> Этикетки на шприцы с иглами | C16: =Упаковка!D12 -> 0 | D16: =Упаковка!E12 -> шт. | E16: =Упаковка!H12*Продукт!$B$7 -> 182150 | F16: =ROUND(E16/12*10,0) -> 151792 | G16: 150000 | J16: =IF((F16-G16)<=0,"ДОСТАТОЧНО",F16-G16) -> 1792
B17: =Упаковка!C13 -> Окись этилена | C17: =Упаковка!D13 -> 0 | D17: =Упаковка!E13 -> кг | E17: =Упаковка!H13*Продукт!$B$7 -> 9337.5 | F17: =ROUND(E17/12*10,0) -> 7781 | G17: 150000 | J17: =IF((F17-G17)<=0,"ДОСТАТОЧНО",F17-G17) -> ДОСТАТОЧНО
A18: =Инструкция!$A$25 -> 3. Вспом. материалы | B18: ='Вспом материалы'!C6 -> Пленка упаковочная блистерная, в рулонах, шириной 422 мм, толщиной 70мкм | C18: ='Вспом материалы'!D6 -> 0 | D18: ='Вспом материалы'!E6 -> кг | E18: ='Вспом материалы'!H6*Продукт!$B$7 -> 106072.73 | F18: =ROUND(E18/12*10,0) -> 88394 | G18: 150000 | J18: =IF((F18-G18)<=0,"ДОСТАТОЧНО",F18-G18) -> ДОСТАТОЧНО
B19: ='Вспом материалы'!C7 -> Бумага для упаковки медицинских изделий марки БГС-60, напечатанная, в рулонах, шириной 415мм | C19: ='Вспом материалы'!D7 -> 0 | D19: ='Вспом материалы'!E7 -> кг | E19: ='Вспом материалы'!H7*Продукт!$B$7 -> 102148.88 | F19: =ROUND(E19/12*10,0) -> 85124 | G19: 150000 | J19: =IF((F19-G19)<=0,"ДОСТАТОЧНО",F19-G19) -> ДОСТАТОЧНО
B20: ='Вспом материалы'!C8 -> Валик для нанесения печати | C20: ='Вспом материалы'!D8 -> 0 | D20: ='Вспом материалы'!E8 -> шт. | E20: ='Вспом материалы'!H8*Продукт!$B$7 -> 2408.85 | F20: =ROUND(E20/12*10,0) -> 2007 | G20: 150000 | J20: =IF((F20-G20)<=0,"ДОСТАТОЧНО",F20-G20) -> ДОСТАТОЧНО
B21: ='Вспом материалы'!C9 -> Игла инъекционная однократного применения размерами 0,6*25мм или 0,7*32мм | C21: ='Вспом материалы'!D9 -> 0 | D21: ='Вспом материалы'!E9 -> шт. | E21: ='Вспом материалы'!H9*Продукт!$B$7 -> 0 | F21: =ROUND(E21/12*10,0) -> 0 | J21: =IF((F21-G21)<=0,"ДОСТАТОЧНО",F21-G21) -> ДОСТАТОЧНО
B22: ='Вспом материалы'!C10 -> Игла инъекционная однократного применения размерами 0,7*32мм или 0,7*38мм | C22: ='Вспом материалы'!D10 -> 0 | D22: ='Вспом материалы'!E10 -> шт. | E22: ='Вспом материалы'!H10*Продукт!$B$7 -> 0 | F22: =ROUND(E22/12*10,0) -> 0 | J22: =IF((F22-G22)<=0,"ДОСТАТОЧНО",F22-G22) -> ДОСТАТОЧНО
B23: ='Вспом материалы'!C11 -> Игла инъекционная однократного применения размерами 0,7*38мм или 0,8*38мм | C23: ='Вспом материалы'!D11 -> 0 | D23: ='Вспом материалы'!E11 -> шт. | E23: ='Вспом материалы'!H11*Продукт!$B$7 -> 252626250 | F23: =ROUND(E23/12*10,0) -> 210521875 | G23: 40000000 | J23: =IF((F23-G23)<=0,"ДОСТАТОЧНО",F23-G23) -> 170521875
B24: ='Вспом материалы'!C12 -> Спирт этиловый | C24: ='Вспом материалы'!D12 -> 0 | D24: ='Вспом материалы'!E12 -> л | E24: ='Вспом материалы'!H12*Продукт!$B$7 -> 154.025 | F24: =ROUND(E24/12*10,0) -> 128 | G24: 4 | J24: =IF((F24-G24)<=0,"ДОСТАТОЧНО",F24-G24) -> 124

Sheet Сырьё
A1: ОСНОВНОЕ СЫРЬЁ И МАТЕРИАЛЫ
A2: Заполните позиции по своему производству. Жёлтые ячейки — ключевые параметры. В конце есть блок "ДОБАВИТЬ ЕЩЁ ПУНКТ".
A4: № | B4: Подкатегория / группа | C4: Наименование позиции | D4: Артикул / код | E4: Ед. изм. | F4: Норма расхода на 1 ед. продукции | G4: % потерь / отходов | H4: Норма с учётом потерь | I4: Цена за единицу | J4: Стоимость на 1 ед. продукции | K4: Стоимость на весь объём выпуска | L4: Поставщик | M4: Срок поставки (дней) | N4: Мин. складской запас | O4: Примечание
A5: Полимеры и пластмассы
A6: 1 | B6: Полимеры и пластмассы | C6: Полипропилен гранулированный | D6: J-560M | E6: кг | F6: 0.00314418 | G6: 0.01 | H6: =IF(F6="","",F6*(1+IFERROR(G6,0))) -> 0.0031756218 | I6: 15000 | J6: =IFERROR(H6*I6,"") -> 47.634327 | K6: =IFERROR(J6*Продукт!B7,"") -> 11908581750
A7: 2 | B7: Полимеры и пластмассы | C7: Скользящая добавка Кродамид марки Crodamide OR BEAD | E7: кг | F7: 9.43e-06 | G7: 0.01 | H7: =IF(F7="","",F7*(1+IFERROR(G7,0))) -> 9.5243e-06 | I7: =126.6*1000 -> 126600 | J7: =IFERROR(H7*I7,"") -> 1.2057764 | K7: =IFERROR(J7*Продукт!B7,"") -> 3.0144409e+08
A8: 3 | B8: Полимеры и пластмассы | C8: Полиэтилен низкого давления марки I-1561 | D8: HDPE I-1561 | E8: кг | F8: 0.00304682 | G8: 0.01 | H8: =IF(F8="","",F8*(1+IFERROR(G8,0))) -> 0.0030772882 | I8: =11.5*1000 -> 11500 | J8: =IFERROR(H8*I8,"") -> 35.388814 | K8: =IFERROR(J8*Продукт!B7,"") -> 8847203575
A9: 4 | B9: Полимеры и пластмассы | C9: Суперконцентрат на основе полиэтилена белый UN-0005 | E9: кг | F9: 9.14e-06 | G9: 0.01 | H9: =IF(F9="","",F9*(1+IFERROR(G9,0))) -> 9.2314e-06 | I9: =84.4*1000 -> 84400 | J9: =IFERROR(H9*I9,"") -> 0.77913016 | K9: =IFERROR(J9*Продукт!B7,"") -> 1.9478254e+08
A10: 5 | B10: Полимеры и пластмассы | C10: Спирт этиловый | E10: л | F10: 1.19e-06 | G10: 0.01 | H10: =IF(F10="","",F10*(1+IFERROR(G10,0))) -> 1.2019e-06 | I10: =15.51511*1000 -> 15515.11 | J10: =IFERROR(H10*I10,"") -> 0.018647611 | K10: =IFERROR(J10*Продукт!B7,"") -> 4661902.7
A11: 6 | B11: Полимеры и пластмассы | H11: =IF(F11="","",F11*(1+IFERROR(G11,0))) | J11: =IFERROR(H11*I11,"") | K11: =IFERROR(J11*Продукт!B7,"")
A12: 7 | B12: Полимеры и пластмассы | H12: =IF(F12="","",F12*(1+IFERROR(G12,0))) | J12: =IFERROR(H12*I12,"") | K12: =IFERROR(J12*Продукт!B7,"")
A13: Металлы и сплавы
A14: 8 | B14: Металлы и сплавы | C14: Сталь листовая | E14: кг | H14: =IF(F14="","",F14*(1+IFERROR(G14,0))) | J14: =IFERROR(H14*I14,"") | K14: =IFERROR(J14*Продукт!B7,"")
A15: 9 | B15: Металлы и сплавы | H15: =IF(F15="","",F15*(1+IFERROR(G15,0))) | J15: =IFERROR(H15*I15,"") | K15: =IFERROR(J15*Продукт!B7,"")
A16: 10 | B16: Металлы и сплавы | H16: =IF(F16="","",F16*(1+IFERROR(G16,0))) | J16: =IFERROR(H16*I16,"") | K16: =IFERROR(J16*Продукт!B7,"")
A17: 11 | B17: Металлы и сплавы | H17: =IF(F17="","",F17*(1+IFERROR(G17,0))) | J17: =IFERROR(H17*I17,"") | K17: =IFERROR(J17*Продукт!B7,"")
A18: 12 | B18: Металлы и сплавы | H18: =IF(F18="","",F18*(1+IFERROR(G18,0))) | J18: =IFERROR(H18*I18,"") | K18: =IFERROR(J18*Продукт!B7,"")
A19: 13 | B19: Металлы и сплавы | H19: =IF(F19="","",F19*(1+IFERROR(G19,0))) | J19: =IFERROR(H19*I19,"") | K19: =IFERROR(J19*Продукт!B7,"")
A20: Древесина и изделия
A21: 14 | B21: Древесина и изделия | C21: Древесина (доска) | E21: м³ | H21: =IF(F21="","",F21*(1+IFERROR(G21,0))) | J21: =IFERROR(H21*I21,"") | K21: =IFERROR(J21*Продукт!B7,"")
A22: 15 | B22: Древесина и изделия | H22: =IF(F22="","",F22*(1+IFERROR(G22,0))) | J22: =IFERROR(H22*I22,"") | K22: =IFERROR(J22*Продукт!B7,"")
A23: 16 | B23: Древесина и изделия | H23: =IF(F23="","",F23*(1+IFERROR(G23,0))) | J23: =IFERROR(H23*I23,"") | K23: =IFERROR(J23*Продукт!B7,"")
A24: 17 | B24: Древесина и изделия | H24: =IF(F24="","",F24*(1+IFERROR(G24,0))) | J24: =IFERROR(H24*I24,"") | K24: =IFERROR(J24*Продукт!B7,"")
A25: 18 | B25: Древесина и изделия | H25: =IF(F25="","",F25*(1+IFERROR(G25,0))) | J25: =IFERROR(H25*I25,"") | K25: =IFERROR(J25*Продукт!B7,"")
A26: 19 | B26: Древесина и изделия | H26: =IF(F26="","",F26*(1+IFERROR(G26,0))) | J26: =IFERROR(H26*I26,"") | K26: =IFERROR(J26*Продукт!B7,"")
A27: Текстиль и волокна
A28: 20 | B28: Текстиль и волокна | C28: Ткань | E28: м | H28: =IF(F28="","",F28*(1+IFERROR(G28,0))) | J28: =IFERROR(H28*I28,"") | K28: =IFERROR(J28*Продукт!B7,"")
A29: 21 | B29: Текстиль и волокна | H29: =IF(F29="","",F29*(1+IFERROR(G29,0))) | J29: =IFERROR(H29*I29,"") | K29: =IFERROR(J29*Продукт!B7,"")
A30: 22 | B30: Текстиль и волокна | H30: =IF(F30="","",F30*(1+IFERROR(G30,0))) | J30: =IFERROR(H30*I30,"") | K30: =IFERROR(J30*Продукт!B7,"")
A31: 23 | B31: Текстиль и волокна | H31: =IF(F31="","",F31*(1+IFERROR(G31,0))) | J31: =IFERROR(H31*I31,"") | K31: =IFERROR(J31*Продукт!B7,"")
A32: 24 | B32: Текстиль и волокна | H32: =IF(F32="","",F32*(1+IFERROR(G32,0))) | J32: =IFERROR(H32*I32,"") | K32: =IFERROR(J32*Продукт!B7,"")
A33: 25 | B33: Текстиль и волокна | H33: =IF(F33="","",F33*(1+IFERROR(G33,0))) | J33: =IFERROR(H33*I33,"") | K33: =IFERROR(J33*Продукт!B7,"")
A34: Пищевое сырьё
A35: 26 | B35: Пищевое сырьё | C35: Мука | E35: кг | H35: =IF(F35="","",F35*(1+IFERROR(G35,0))) | J35: =IFERROR(H35*I35,"") | K35: =IFERROR(J35*Продукт!B7,"")
A36: 27 | B36: Пищевое сырьё | H36: =IF(F36="","",F36*(1+IFERROR(G36,0))) | J36: =IFERROR(H36*I36,"") | K36: =IFERROR(J36*Продукт!B7,"")
A37: 28 | B37: Пищевое сырьё | H37: =IF(F37="","",F37*(1+IFERROR(G37,0))) | J37: =IFERROR(H37*I37,"") | K37: =IFERROR(J37*Продукт!B7,"")
A38: 29 | B38: Пищевое сырьё | H38: =IF(F38="","",F38*(1+IFERROR(G38,0))) | J38: =IFERROR(H38*I38,"") | K38: =IFERROR(J38*Продукт!B7,"")
A39: 30 | B39: Пищевое сырьё | H39: =IF(F39="","",F39*(1+IFERROR(G39,0))) | J39: =IFERROR(H39*I39,"") | K39: =IFERROR(J39*Продукт!B7,"")
A40: 31 | B40: Пищевое сырьё | H40: =IF(F40="","",F40*(1+IFERROR(G40,0))) | J40: =IFERROR(H40*I40,"") | K40: =IFERROR(J40*Продукт!B7,"")
A41: Химическое сырьё
...

Sheet Вспом материалы
A1: ВСПОМОГАТЕЛЬНЫЕ МАТЕРИАЛЫ И ДОБАВКИ
A2: Заполните позиции по своему производству. Жёлтые ячейки — ключевые параметры. В конце есть блок "ДОБАВИТЬ ЕЩЁ ПУНКТ".
A4: № | B4: Подкатегория / группа | C4: Наименование позиции | D4: Артикул / код | E4: Ед. изм. | F4: Норма расхода на 1 ед. продукции | G4: % потерь / отходов | H4: Норма с учётом потерь | I4: Цена за единицу | J4: Стоимость на 1 ед. продукции | K4: Стоимость на весь объём выпуска | L4: Поставщик | M4: Срок поставки (дней) | N4: Мин. складской запас | O4: Примечание
A5: Добавки и модификаторы
A6: 1 | B6: Добавки и модификаторы | C6: Пленка упаковочная блистерная, в рулонах, шириной 422 мм, толщиной 70мкм | E6: кг | F6: 0.00042009 | G6: 0.01 | H6: =IF(F6="","",F6*(1+IFERROR(G6,0))) -> 0.0004242909 | I6: =21.1*1000 -> 21100 | J6: =IFERROR(H6*I6,"") -> 8.952538 | K6: =IFERROR(J6*Продукт!B7,"") -> 2.2381345e+09 | L6: =H6*Продукт!B7 -> 106072.73
A7: 2 | B7: Добавки и модификаторы | C7: Бумага для упаковки медицинских изделий марки БГС-60, напечатанная, в рулонах, шириной 415мм | E7: кг | F7: 0.00040455 | G7: 0.01 | H7: =IF(F7="","",F7*(1+IFERROR(G7,0))) -> 0.0004085955 | I7: =20.045*1000 -> 20045 | J7: =IFERROR(H7*I7,"") -> 8.1902968 | K7: =IFERROR(J7*Продукт!B7,"") -> 2.0475742e+09
A8: 3 | B8: Добавки и модификаторы | C8: Валик для нанесения печати | E8: шт. | F8: 9.54e-06 | G8: 0.01 | H8: =IF(F8="","",F8*(1+IFERROR(G8,0))) -> 9.6354e-06 | I8: =15*1000 -> 15000 | J8: =IFERROR(H8*I8,"") -> 0.144531 | K8: =IFERROR(J8*Продукт!B7,"") -> 36132750
A9: 4 | B9: Добавки и модификаторы | C9: Игла инъекционная однократного применения размерами 0,6*25мм или 0,7*32мм | E9: шт. | F9: 0 | G9: 0.01 | H9: =IF(F9="","",F9*(1+IFERROR(G9,0))) -> 0 | I9: =0.05908*1000 -> 59.08 | J9: =IFERROR(H9*I9,"") -> 0 | K9: =IFERROR(J9*Продукт!B7,"") -> 0
A10: 5 | B10: Добавки и модификаторы | C10: Игла инъекционная однократного применения размерами 0,7*32мм или 0,7*38мм | E10: шт. | F10: 0 | G10: 0.01 | H10: =IF(F10="","",F10*(1+IFERROR(G10,0))) -> 0 | I10: =0.05908*1000 -> 59.08 | J10: =IFERROR(H10*I10,"") -> 0 | K10: =IFERROR(J10*Продукт!B7,"") -> 0
A11: 6 | B11: Добавки и модификаторы | C11: Игла инъекционная однократного применения размерами 0,7*38мм или 0,8*38мм | E11: шт. | F11: 1.0005 | G11: 0.01 | H11: =IF(F11="","",F11*(1+IFERROR(G11,0))) -> 1.010505 | I11: =0.05908*1000 -> 59.08 | J11: =IFERROR(H11*I11,"") -> 59.700635 | K11: =IFERROR(J11*Продукт!B7,"") -> 1.4925159e+10
A12: 7 | B12: Добавки и модификаторы | C12: Спирт этиловый | E12: л | F12: 6.1e-07 | G12: 0.01 | H12: =IF(F12="","",F12*(1+IFERROR(G12,0))) -> 6.161e-07 | I12: =15.51511*1000 -> 15515.11 | J12: =IFERROR(H12*I12,"") -> 0.0095588593 | K12: =IFERROR(J12*Продукт!B7,"") -> 2389714.8
A13: 8 | B13: Добавки и модификаторы | H13: =IF(F13="","",F13*(1+IFERROR(G13,0))) | J13: =IFERROR(H13*I13,"") | K13: =IFERROR(J13*Продукт!B7,"")
A14: Клеи, герметики, смазки технологические
A15: 9 | B15: Клеи, герметики, смазки технологические | C15: Клей промышленный | E15: кг | H15: =IF(F15="","",F15*(1+IFERROR(G15,0))) | J15: =IFERROR(H15*I15,"") | K15: =IFERROR(J15*Продукт!B7,"")
A16: 10 | B16: Клеи, герметики, смазки технологические | C16: Разделительная смазка для форм | E16: л | H16: =IF(F16="","",F16*(1+IFERROR(G16,0))) | J16: =IFERROR(H16*I16,"") | K16: =IFERROR(J16*Продукт!B7,"")
A17: 11 | B17: Клеи, герметики, смазки технологические | H17: =IF(F17="","",F17*(1+IFERROR(G17,0))) | J17: =IFERROR(H17*I17,"") | K17: =IFERROR(J17*Продукт!B7,"")
A18: 12 | B18: Клеи, герметики, смазки технологические | H18: =IF(F18="","",F18*(1+IFERROR(G18,0))) | J18: =IFERROR(H18*I18,"") | K18: =IFERROR(J18*Продукт!B7,"")
A19: 13 | B19: Клеи, герметики, смазки технологические | H19: =IF(F19="","",F19*(1+IFERROR(G19,0))) | J19: =IFERROR(H19*I19,"") | K19: =IFERROR(J19*Продукт!B7,"")
A20: 14 | B20: Клеи, герметики, смазки технологические | H20: =IF(F20="","",F20*(1+IFERROR(G20,0))) | J20: =IFERROR(H20*I20,"") | K20: =IFERROR(J20*Продукт!B7,"")
A21: 15 | B21: Клеи, герметики, смазки технологические | H21: =IF(F21="","",F21*(1+IFERROR(G21,0))) | J21: =IFERROR(H21*I21,"") | K21: =IFERROR(J21*Продукт!B7,"")
A22: Реактивы и химикаты процесса
A23: 16 | B23: Реактивы и химикаты процесса | C23: Реактив технологический | E23: кг | H23: =IF(F23="","",F23*(1+IFERROR(G23,0))) | J23: =IFERROR(H23*I23,"") | K23: =IFERROR(J23*Продукт!B7,"")
A24: 17 | B24: Реактивы и химикаты процесса | H24: =IF(F24="","",F24*(1+IFERROR(G24,0))) | J24: =IFERROR(H24*I24,"") | K24: =IFERROR(J24*Продукт!B7,"")
A25: 18 | B25: Реактивы и химикаты процесса | H25: =IF(F25="","",F25*(1+IFERROR(G25,0))) | J25: =IFERROR(H25*I25,"") | K25: =IFERROR(J25*Продукт!B7,"")
A26: 19 | B26: Реактивы и химикаты процесса | H26: =IF(F26="","",F26*(1+IFERROR(G26,0))) | J26: =IFERROR(H26*I26,"") | K26: =IFERROR(J26*Продукт!B7,"")
A27: 20 | B27: Реактивы и химикаты процесса | H27: =IF(F27="","",F27*(1+IFERROR(G27,0))) | J27: =IFERROR(H27*I27,"") | K27: =IFERROR(J27*Продукт!B7,"")
A28: 21 | B28: Реактивы и химикаты процесса | H28: =IF(F28="","",F28*(1+IFERROR(G28,0))) | J28: =IFERROR(H28*I28,"") | K28: =IFERROR(J28*Продукт!B7,"")
A29: + ДОБАВИТЬ ЕЩЁ ПУНКТ (вставляйте строки выше или дописывайте здесь)
A30: 22 | H30: =IF(F30="","",F30*(1+IFERROR(G30,0))) | J30: =IFERROR(H30*I30,"") | K30: =IFERROR(J30*Продукт!B7,"")
A31: 23 | H31: =IF(F31="","",F31*(1+IFERROR(G31,0))) | J31: =IFERROR(H31*I31,"") | K31: =IFERROR(J31*Продукт!B7,"")
A32: 24 | H32: =IF(F32="","",F32*(1+IFERROR(G32,0))) | J32: =IFERROR(H32*I32,"") | K32: =IFERROR(J32*Продукт!B7,"")
A33: 25 | H33: =IF(F33="","",F33*(1+IFERROR(G33,0))) | J33: =IFERROR(H33*I33,"") | K33: =IFERROR(J33*Продукт!B7,"")
A34: 26 | H34: =IF(F34="","",F34*(1+IFERROR(G34,0))) | J34: =IFERROR(H34*I34,"") | K34: =IFERROR(J34*Продукт!B7,"")
A36: ИТОГО ПО КАТЕГОРИИ: | J36: =SUMIF(J5:J34,">0") -> 76.99756 | K36: =SUMIF(K5:K34,">0") -> 1.924939e+10

Sheet Упаковка
A1: УПАКОВОЧНЫЕ МАТЕРИАЛЫ
A2: Заполните позиции по своему производству. Жёлтые ячейки — ключевые параметры. В конце есть блок "ДОБАВИТЬ ЕЩЁ ПУНКТ".
A4: № | B4: Подкатегория / группа | C4: Наименование позиции | D4: Артикул / код | E4: Ед. изм. | F4: Норма расхода на 1 ед. продукции | G4: % потерь / отходов | H4: Норма с учётом потерь | I4: Цена за единицу | J4: Стоимость на 1 ед. продукции | K4: Стоимость на весь объём выпуска | L4: Поставщик | M4: Срок поставки (дней) | N4: Мин. складской запас | O4: Примечание
A5: Первичная упаковка (контакт с продуктом)
A6: 1 | B6: Первичная упаковка (контакт с продуктом) | C6: Упаковочный лист для ящиков | E6: шт. | F6: 0.0007286 | H6: =IF(F6="","",F6*(1+IFERROR(G6,0))) -> 0.0007286 | I6: 250 | J6: =IFERROR(H6*I6,"") -> 0.18215 | K6: =IFERROR(J6*Продукт!B7,"") -> 45537500
A7: 2 | B7: Первичная упаковка (контакт с продуктом) | C7: Инструкция на шприцы | E7: шт. | F7: 0.0007286 | H7: =IF(F7="","",F7*(1+IFERROR(G7,0))) -> 0.0007286 | I7: 115 | J7: =IFERROR(H7*I7,"") -> 0.083789 | K7: =IFERROR(J7*Продукт!B7,"") -> 20947250
A8: 3 | B8: Первичная упаковка (контакт с продуктом) | C8: Ящики упаковочные из гофрированного картона размерами 600*400*430 мм | E8: шт. | F8: 0.0007179 | H8: =IF(F8="","",F8*(1+IFERROR(G8,0))) -> 0.0007179 | I8: 6900 | J8: =IFERROR(H8*I8,"") -> 4.95351 | K8: =IFERROR(J8*Продукт!B7,"") -> 1238377500
A9: 4 | B9: Первичная упаковка (контакт с продуктом) | C9: Вкладыши для ящика, по 2шт. На ящик, размером 550*330мм | E9: шт. | F9: 0.001429 | H9: =IF(F9="","",F9*(1+IFERROR(G9,0))) -> 0.001429 | I9: 1208 | J9: =IFERROR(H9*I9,"") -> 1.726232 | K9: =IFERROR(J9*Продукт!B7,"") -> 431558000
A10: 5 | B10: Первичная упаковка (контакт с продуктом) | C10: Скобы для ящика размерами 15*35мм, по 2шт. На ящик | E10: шт. | F10: 0.001486 | H10: =IF(F10="","",F10*(1+IFERROR(G10,0))) -> 0.001486 | I10: 50 | J10: =IFERROR(H10*I10,"") -> 0.0743 | K10: =IFERROR(J10*Продукт!B7,"") -> 18575000
A11: 6 | B11: Первичная упаковка (контакт с продуктом) | C11: Скотч лента, в рулонах, длиной 100м. | E11: шт. | F11: 5.94e-06 | H11: =IF(F11="","",F11*(1+IFERROR(G11,0))) -> 5.94e-06 | I11: 17500 | J11: =IFERROR(H11*I11,"") -> 0.10395 | K11: =IFERROR(J11*Продукт!B7,"") -> 25987500
A12: 7 | B12: Первичная упаковка (контакт с продуктом) | C12: Этикетки на шприцы с иглами | E12: шт. | F12: 0.0007286 | H12: =IF(F12="","",F12*(1+IFERROR(G12,0))) -> 0.0007286 | I12: 271 | J12: =IFERROR(H12*I12,"") -> 0.1974506 | K12: =IFERROR(J12*Продукт!B7,"") -> 49362650
A13: 8 | B13: Первичная упаковка (контакт с продуктом) | C13: Окись этилена | E13: кг | F13: 3.735e-05 | H13: =IF(F13="","",F13*(1+IFERROR(G13,0))) -> 3.735e-05 | I13: 116050 | J13: =IFERROR(H13*I13,"") -> 4.3344675 | K13: =IFERROR(J13*Продукт!B7,"") -> 1083616875
A14: Вторичная упаковка
A15: 9 | B15: Вторичная упаковка | C15: Коробка картонная | E15: шт | H15: =IF(F15="","",F15*(1+IFERROR(G15,0))) | J15: =IFERROR(H15*I15,"") | K15: =IFERROR(J15*Продукт!B7,"")
A16: 10 | B16: Вторичная упаковка | C16: Этикетка | E16: шт | H16: =IF(F16="","",F16*(1+IFERROR(G16,0))) | J16: =IFERROR(H16*I16,"") | K16: =IFERROR(J16*Продукт!B7,"")
A17: 11 | B17: Вторичная упаковка | C17: Инструкция (вкладыш) | E17: шт | H17: =IF(F17="","",F17*(1+IFERROR(G17,0))) | J17: =IFERROR(H17*I17,"") | K17: =IFERROR(J17*Продукт!B7,"")
A18: 12 | B18: Вторичная упаковка | H18: =IF(F18="","",F18*(1+IFERROR(G18,0))) | J18: =IFERROR(H18*I18,"") | K18: =IFERROR(J18*Продукт!B7,"")
A19: 13 | B19: Вторичная упаковка | H19: =IF(F19="","",F19*(1+IFERROR(G19,0))) | J19: =IFERROR(H19*I19,"") | K19: =IFERROR(J19*Продукт!B7,"")
A20: 14 | B20: Вторичная упаковка | H20: =IF(F20="","",F20*(1+IFERROR(G20,0))) | J20: =IFERROR(H20*I20,"") | K20: =IFERROR(J20*Продукт!B7,"")
A21: 15 | B21: Вторичная упаковка | H21: =IF(F21="","",F21*(1+IFERROR(G21,0))) | J21: =IFERROR(H21*I21,"") | K21: =IFERROR(J21*Продукт!B7,"")
A22: 16 | B22: Вторичная упаковка | H22: =IF(F22="","",F22*(1+IFERROR(G22,0))) | J22: =IFERROR(H22*I22,"") | K22: =IFERROR(J22*Продукт!B7,"")
A23: Транспортная упаковка
A24: 17 | B24: Транспортная упаковка | C24: Гофрокороб | E24: шт | H24: =IF(F24="","",F24*(1+IFERROR(G24,0))) | J24: =IFERROR(H24*I24,"") | K24: =IFERROR(J24*Продукт!B7,"")
A25: 18 | B25: Транспортная упаковка | C25: Стрейч-плёнка | E25: м | H25: =IF(F25="","",F25*(1+IFERROR(G25,0))) | J25: =IFERROR(H25*I25,"") | K25: =IFERROR(J25*Продукт!B7,"")
A26: 19 | B26: Транспортная упаковка | C26: Скотч упаковочный | E26: м | H26: =IF(F26="","",F26*(1+IFERROR(G26,0))) | J26: =IFERROR(H26*I26,"") | K26: =IFERROR(J26*Продукт!B7,"")
A27: 20 | B27: Транспортная упаковка | C27: Паллета деревянная | E27: шт | H27: =IF(F27="","",F27*(1+IFERROR(G27,0))) | J27: =IFERROR(H27*I27,"") | K27: =IFERROR(J27*Продукт!B7,"")
A28: 21 | B28: Транспортная упаковка | H28: =IF(F28="","",F28*(1+IFERROR(G28,0))) | J28: =IFERROR(H28*I28,"") | K28: =IFERROR(J28*Продукт!B7,"")
A29: 22 | B29: Транспортная упаковка | H29: =IF(F29="","",F29*(1+IFERROR(G29,0))) | J29: =IFERROR(H29*I29,"") | K29: =IFERROR(J29*Продукт!B7,"")
A30: 23 | B30: Транспортная упаковка | H30: =IF(F30="","",F30*(1+IFERROR(G30,0))) | J30: =IFERROR(H30*I30,"") | K30: =IFERROR(J30*Продукт!B7,"")
A31: 24 | B31: Транспортная упаковка | H31: =IF(F31="","",F31*(1+IFERROR(G31,0))) | J31: =IFERROR(H31*I31,"") | K31: =IFERROR(J31*Продукт!B7,"")
A32: 25 | B32: Транспортная упаковка | H32: =IF(F32="","",F32*(1+IFERROR(G32,0))) | J32: =IFERROR(H32*I32,"") | K32: =IFERROR(J32*Продукт!B7,"")
A33: + ДОБАВИТЬ ЕЩЁ ПУНКТ (вставляйте строки выше или дописывайте здесь)
A34: 26 | H34: =IF(F34="","",F34*(1+IFERROR(G34,0))) | J34: =IFERROR(H34*I34,"") | K34: =IFERROR(J34*Продукт!B7,"")
A35: 27 | H35: =IF(F35="","",F35*(1+IFERROR(G35,0))) | J35: =IFERROR(H35*I35,"") | K35: =IFERROR(J35*Продукт!B7,"")
A36: 28 | H36: =IF(F36="","",F36*(1+IFERROR(G36,0))) | J36: =IFERROR(H36*I36,"") | K36: =IFERROR(J36*Продукт!B7,"")
A37: 29 | H37: =IF(F37="","",F37*(1+IFERROR(G37,0))) | J37: =IFERROR(H37*I37,"") | K37: =IFERROR(J37*Продукт!B7,"")
A38: 30 | H38: =IF(F38="","",F38*(1+IFERROR(G38,0))) | J38: =IFERROR(H38*I38,"") | K38: =IFERROR(J38*Продукт!B7,"")
A40: ИТОГО ПО КАТЕГОРИИ: | J40: =SUMIF(J5:J38,">0") -> 11.655849 | K40: =SUMIF(K5:K38,">0") -> 2913962275

Sheet Комплектующие
A1: КОМПЛЕКТУЮЩИЕ И ПОЛУФАБРИКАТЫ
A2: Заполните позиции по своему производству. Жёлтые ячейки — ключевые параметры. В конце есть блок "ДОБАВИТЬ ЕЩЁ ПУНКТ".
A4: № | B4: Подкатегория / группа | C4: Наименование позиции | D4: Артикул / код | E4: Ед. изм. | F4: Норма расхода на 1 ед. продукции | G4: % потерь / отходов | H4: Норма с учётом потерь | I4: Цена за единицу | J4: Стоимость на 1 ед. продукции | K4: Стоимость на весь объём выпуска | L4: Поставщик | M4: Срок поставки (дней) | N4: Мин. складской запас | O4: Примечание
A5: Готовые детали (покупные)
A6: 1 | B6: Готовые детали (покупные) | C6: Деталь / узел №1 | E6: шт | H6: =IF(F6="","",F6*(1+IFERROR(G6,0))) | J6: =IFERROR(H6*I6,"") | K6: =IFERROR(J6*Продукт!B7,"")
A7: 2 | B7: Готовые детали (покупные) | H7: =IF(F7="","",F7*(1+IFERROR(G7,0))) | J7: =IFERROR(H7*I7,"") | K7: =IFERROR(J7*Продукт!B7,"")
A8: 3 | B8: Готовые детали (покупные) | H8: =IF(F8="","",F8*(1+IFERROR(G8,0))) | J8: =IFERROR(H8*I8,"") | K8: =IFERROR(J8*Продукт!B7,"")
A9: 4 | B9: Готовые детали (покупные) | H9: =IF(F9="","",F9*(1+IFERROR(G9,0))) | J9: =IFERROR(H9*I9,"") | K9: =IFERROR(J9*Продукт!B7,"")
A10: 5 | B10: Готовые детали (покупные) | H10: =IF(F10="","",F10*(1+IFERROR(G10,0))) | J10: =IFERROR(H10*I10,"") | K10: =IFERROR(J10*Продукт!B7,"")
A11: 6 | B11: Готовые детали (покупные) | H11: =IF(F11="","",F11*(1+IFERROR(G11,0))) | J11: =IFERROR(H11*I11,"") | K11: =IFERROR(J11*Продукт!B7,"")
A12: Крепёж и метизы
A13: 7 | B13: Крепёж и метизы | C13: Винт / болт | E13: шт | H13: =IF(F13="","",F13*(1+IFERROR(G13,0))) | J13: =IFERROR(H13*I13,"") | K13: =IFERROR(J13*Продукт!B7,"")
A14: 8 | B14: Крепёж и метизы | C14: Гайка | E14: шт | H14: =IF(F14="","",F14*(1+IFERROR(G14,0))) | J14: =IFERROR(H14*I14,"") | K14: =IFERROR(J14*Продукт!B7,"")
A15: 9 | B15: Крепёж и метизы | C15: Шайба | E15: шт | H15: =IF(F15="","",F15*(1+IFERROR(G15,0))) | J15: =IFERROR(H15*I15,"") | K15: =IFERROR(J15*Продукт!B7,"")
A16: 10 | B16: Крепёж и метизы | H16: =IF(F16="","",F16*(1+IFERROR(G16,0))) | J16: =IFERROR(H16*I16,"") | K16: =IFERROR(J16*Продукт!B7,"")
A17: 11 | B17: Крепёж и метизы | H17: =IF(F17="","",F17*(1+IFERROR(G17,0))) | J17: =IFERROR(H17*I17,"") | K17: =IFERROR(J17*Продукт!B7,"")
A18: 12 | B18: Крепёж и метизы | H18: =IF(F18="","",F18*(1+IFERROR(G18,0))) | J18: =IFERROR(H18*I18,"") | K18: =IFERROR(J18*Продукт!B7,"")
A19: 13 | B19: Крепёж и метизы | H19: =IF(F19="","",F19*(1+IFERROR(G19,0))) | J19: =IFERROR(H19*I19,"") | K19: =IFERROR(J19*Продукт!B7,"")
A20: 14 | B20: Крепёж и метизы | H20: =IF(F20="","",F20*(1+IFERROR(G20,0))) | J20: =IFERROR(H20*I20,"") | K20: =IFERROR(J20*Продукт!B7,"")
A21: Электронные компоненты
A22: 15 | B22: Электронные компоненты | C22: Плата / модуль | E22: шт | H22: =IF(F22="","",F22*(1+IFERROR(G22,0))) | J22: =IFERROR(H22*I22,"") | K22: =IFERROR(J22*Продукт!B7,"")
A23: 16 | B23: Электронные компоненты | H23: =IF(F23="","",F23*(1+IFERROR(G23,0))) | J23: =IFERROR(H23*I23,"") | K23: =IFERROR(J23*Продукт!B7,"")
A24: 17 | B24: Электронные компоненты | H24: =IF(F24="","",F24*(1+IFERROR(G24,0))) | J24: =IFERROR(H24*I24,"") | K24: =IFERROR(J24*Продукт!B7,"")
A25: 18 | B25: Электронные компоненты | H25: =IF(F25="","",F25*(1+IFERROR(G25,0))) | J25: =IFERROR(H25*I25,"") | K25: =IFERROR(J25*Продукт!B7,"")
A26: 19 | B26: Электронные компоненты | H26: =IF(F26="","",F26*(1+IFERROR(G26,0))) | J26: =IFERROR(H26*I26,"") | K26: =IFERROR(J26*Продукт!B7,"")
A27: 20 | B27: Электронные компоненты | H27: =IF(F27="","",F27*(1+IFERROR(G27,0))) | J27: =IFERROR(H27*I27,"") | K27: =IFERROR(J27*Продукт!B7,"")
A28: + ДОБАВИТЬ ЕЩЁ ПУНКТ (вставляйте строки выше или дописывайте здесь)
A29: 21 | H29: =IF(F29="","",F29*(1+IFERROR(G29,0))) | J29: =IFERROR(H29*I29,"") | K29: =IFERROR(J29*Продукт!B7,"")
A30: 22 | H30: =IF(F30="","",F30*(1+IFERROR(G30,0))) | J30: =IFERROR(H30*I30,"") | K30: =IFERROR(J30*Продукт!B7,"")
A31: 23 | H31: =IF(F31="","",F31*(1+IFERROR(G31,0))) | J31: =IFERROR(H31*I31,"") | K31: =IFERROR(J31*Продукт!B7,"")
A32: 24 | H32: =IF(F32="","",F32*(1+IFERROR(G32,0))) | J32: =IFERROR(H32*I32,"") | K32: =IFERROR(J32*Продукт!B7,"")
A33: 25 | H33: =IF(F33="","",F33*(1+IFERROR(G33,0))) | J33: =IFERROR(H33*I33,"") | K33: =IFERROR(J33*Продукт!B7,"")
A35: ИТОГО ПО КАТЕГОРИИ: | J35: =SUMIF(J5:J33,">0") -> 0 | K35: =SUMIF(K5:K33,">0") -> 0

Sheet Оборудование
A1: ОБОРУДОВАНИЕ (ОСНОВНЫЕ СРЕДСТВА)
A2: Заполните позиции по своему производству. Жёлтые ячейки — ключевые параметры. В конце есть блок "ДОБАВИТЬ ЕЩЁ ПУНКТ".
A4: № | B4: Подкатегория / группа | C4: Наименование позиции | D4: Артикул / код | E4: Ед. изм. | F4: Норма расхода на 1 ед. продукции | G4: % потерь / отходов | H4: Норма с учётом потерь | I4: Цена за единицу | J4: Стоимость на 1 ед. продукции | K4: Стоимость на весь объём выпуска | L4: Поставщик | M4: Срок поставки (дней) | N4: Мин. складской запас | O4: Примечание
A5: Основное технологическое оборудование
A6: 1 | B6: Основное технологическое оборудование | C6: Литейная машина (ТПА) | E6: шт | H6: =IF(F6="","",F6*(1+IFERROR(G6,0))) | J6: =IFERROR(H6*I6,"") | K6: =IFERROR(J6*Продукт!B7,"")
A7: 2 | B7: Основное технологическое оборудование | C7: Экструдер | E7: шт | H7: =IF(F7="","",F7*(1+IFERROR(G7,0))) | J7: =IFERROR(H7*I7,"") | K7: =IFERROR(J7*Продукт!B7,"")
A8: 3 | B8: Основное технологическое оборудование | C8: Сборочная линия | E8: шт | H8: =IF(F8="","",F8*(1+IFERROR(G8,0))) | J8: =IFERROR(H8*I8,"") | K8: =IFERROR(J8*Продукт!B7,"")
A9: 4 | B9: Основное технологическое оборудование | H9: =IF(F9="","",F9*(1+IFERROR(G9,0))) | J9: =IFERROR(H9*I9,"") | K9: =IFERROR(J9*Продукт!B7,"")
A10: 5 | B10: Основное технологическое оборудование | H10: =IF(F10="","",F10*(1+IFERROR(G10,0))) | J10: =IFERROR(H10*I10,"") | K10: =IFERROR(J10*Продукт!B7,"")
A11: 6 | B11: Основное технологическое оборудование | H11: =IF(F11="","",F11*(1+IFERROR(G11,0))) | J11: =IFERROR(H11*I11,"") | K11: =IFERROR(J11*Продукт!B7,"")
A12: 7 | B12: Основное технологическое оборудование | H12: =IF(F12="","",F12*(1+IFERROR(G12,0))) | J12: =IFERROR(H12*I12,"") | K12: =IFERROR(J12*Продукт!B7,"")
A13: 8 | B13: Основное технологическое оборудование | H13: =IF(F13="","",F13*(1+IFERROR(G13,0))) | J13: =IFERROR(H13*I13,"") | K13: =IFERROR(J13*Продукт!B7,"")
A14: Вспомогательное оборудование
A15: 9 | B15: Вспомогательное оборудование | C15: Компрессор | E15: шт | H15: =IF(F15="","",F15*(1+IFERROR(G15,0))) | J15: =IFERROR(H15*I15,"") | K15: =IFERROR(J15*Продукт!B7,"")
A16: 10 | B16: Вспомогательное оборудование | C16: Чиллер / охладитель | E16: шт | H16: =IF(F16="","",F16*(1+IFERROR(G16,0))) | J16: =IFERROR(H16*I16,"") | K16: =IFERROR(J16*Продукт!B7,"")
A17: 11 | B17: Вспомогательное оборудование | C17: Сушилка для сырья | E17: шт | H17: =IF(F17="","",F17*(1+IFERROR(G17,0))) | J17: =IFERROR(H17*I17,"") | K17: =IFERROR(J17*Продукт!B7,"")
A18: 12 | B18: Вспомогательное оборудование | H18: =IF(F18="","",F18*(1+IFERROR(G18,0))) | J18: =IFERROR(H18*I18,"") | K18: =IFERROR(J18*Продукт!B7,"")
A19: 13 | B19: Вспомогательное оборудование | H19: =IF(F19="","",F19*(1+IFERROR(G19,0))) | J19: =IFERROR(H19*I19,"") | K19: =IFERROR(J19*Продукт!B7,"")
A20: 14 | B20: Вспомогательное оборудование | H20: =IF(F20="","",F20*(1+IFERROR(G20,0))) | J20: =IFERROR(H20*I20,"") | K20: =IFERROR(J20*Продукт!B7,"")
A21: 15 | B21: Вспомогательное оборудование | H21: =IF(F21="","",F21*(1+IFERROR(G21,0))) | J21: =IFERROR(H21*I21,"") | K21: =IFERROR(J21*Продукт!B7,"")
A22: 16 | B22: Вспомогательное оборудование | H22: =IF(F22="","",F22*(1+IFERROR(G22,0))) | J22: =IFERROR(H22*I22,"") | K22: =IFERROR(J22*Продукт!B7,"")
A23: Транспортное и складское оборудование
A24: 17 | B24: Транспортное и складское оборудование | C24: Конвейер | E24: шт | H24: =IF(F24="","",F24*(1+IFERROR(G24,0))) | J24: =IFERROR(H24*I24,"") | K24: =IFERROR(J24*Продукт!B7,"")
A25: 18 | B25: Транспортное и складское оборудование | C25: Погрузчик / штабелёр | E25: шт | H25: =IF(F25="","",F25*(1+IFERROR(G25,0))) | J25: =IFERROR(H25*I25,"") | K25: =IFERROR(J25*Продукт!B7,"")
A26: 19 | B26: Транспортное и складское оборудование | H26: =IF(F26="","",F26*(1+IFERROR(G26,0))) | J26: =IFERROR(H26*I26,"") | K26: =IFERROR(J26*Продукт!B7,"")
A27: 20 | B27: Транспортное и складское оборудование | H27: =IF(F27="","",F27*(1+IFERROR(G27,0))) | J27: =IFERROR(H27*I27,"") | K27: =IFERROR(J27*Продукт!B7,"")
A28: 21 | B28: Транспортное и складское оборудование | H28: =IF(F28="","",F28*(1+IFERROR(G28,0))) | J28: =IFERROR(H28*I28,"") | K28: =IFERROR(J28*Продукт!B7,"")
A29: 22 | B29: Транспортное и складское оборудование | H29: =IF(F29="","",F29*(1+IFERROR(G29,0))) | J29: =IFERROR(H29*I29,"") | K29: =IFERROR(J29*Продукт!B7,"")
A30: 23 | B30: Транспортное и складское оборудование | H30: =IF(F30="","",F30*(1+IFERROR(G30,0))) | J30: =IFERROR(H30*I30,"") | K30: =IFERROR(J30*Продукт!B7,"")
A31: + ДОБАВИТЬ ЕЩЁ ПУНКТ (вставляйте строки выше или дописывайте здесь)
A32: 24 | H32: =IF(F32="","",F32*(1+IFERROR(G32,0))) | J32: =IFERROR(H32*I32,"") | K32: =IFERROR(J32*Продукт!B7,"")
A33: 25 | H33: =IF(F33="","",F33*(1+IFERROR(G33,0))) | J33: =IFERROR(H33*I33,"") | K33: =IFERROR(J33*Продукт!B7,"")
A34: 26 | H34: =IF(F34="","",F34*(1+IFERROR(G34,0))) | J34: =IFERROR(H34*I34,"") | K34: =IFERROR(J34*Продукт!B7,"")
A35: 27 | H35: =IF(F35="","",F35*(1+IFERROR(G35,0))) | J35: =IFERROR(H35*I35,"") | K35: =IFERROR(J35*Продукт!B7,"")
A36: 28 | H36: =IF(F36="","",F36*(1+IFERROR(G36,0))) | J36: =IFERROR(H36*I36,"") | K36: =IFERROR(J36*Продукт!B7,"")
A38: ИТОГО ПО КАТЕГОРИИ: | J38: =SUMIF(J5:J36,">0") -> 0 | K38: =SUMIF(K5:K36,">0") -> 0

Sheet Оснастка
A1: ОСНАСТКА И ИНСТРУМЕНТ
A2: Заполните позиции по своему производству. Жёлтые ячейки — ключевые параметры. В конце есть блок "ДОБАВИТЬ ЕЩЁ ПУНКТ".
A4: № | B4: Подкатегория / группа | C4: Наименование позиции | D4: Артикул / код | E4: Ед. изм. | F4: Норма расхода на 1 ед. продукции | G4: % потерь / отходов | H4: Норма с учётом потерь | I4: Цена за единицу | J4: Стоимость на 1 ед. продукции | K4: Стоимость на весь объём выпуска | L4: Поставщик | M4: Срок поставки (дней) | N4: Мин. складской запас | O4: Примечание
A5: Формообразующая оснастка
A6: 1 | B6: Формообразующая оснастка | C6: Пресс-форма | E6: шт | H6: =IF(F6="","",F6*(1+IFERROR(G6,0))) | J6: =IFERROR(H6*I6,"") | K6: =IFERROR(J6*Продукт!B7,"")
A7: 2 | B7: Формообразующая оснастка | C7: Штамп | E7: шт | H7: =IF(F7="","",F7*(1+IFERROR(G7,0))) | J7: =IFERROR(H7*I7,"") | K7: =IFERROR(J7*Продукт!B7,"")
A8: 3 | B8: Формообразующая оснастка | C8: Матрица / пуансон | E8: шт | H8: =IF(F8="","",F8*(1+IFERROR(G8,0))) | J8: =IFERROR(H8*I8,"") | K8: =IFERROR(J8*Продукт!B7,"")
A9: 4 | B9: Формообразующая оснастка | H9: =IF(F9="","",F9*(1+IFERROR(G9,0))) | J9: =IFERROR(H9*I9,"") | K9: =IFERROR(J9*Продукт!B7,"")
A10: 5 | B10: Формообразующая оснастка | H10: =IF(F10="","",F10*(1+IFERROR(G10,0))) | J10: =IFERROR(H10*I10,"") | K10: =IFERROR(J10*Продукт!B7,"")
A11: 6 | B11: Формообразующая оснастка | H11: =IF(F11="","",F11*(1+IFERROR(G11,0))) | J11: =IFERROR(H11*I11,"") | K11: =IFERROR(J11*Продукт!B7,"")
A12: 7 | B12: Формообразующая оснастка | H12: =IF(F12="","",F12*(1+IFERROR(G12,0))) | J12: =IFERROR(H12*I12,"") | K12: =IFERROR(J12*Продукт!B7,"")
A13: 8 | B13: Формообразующая оснастка | H13: =IF(F13="","",F13*(1+IFERROR(G13,0))) | J13: =IFERROR(H13*I13,"") | K13: =IFERROR(J13*Продукт!B7,"")
A14: Режущий и обрабатывающий инструмент
A15: 9 | B15: Режущий и обрабатывающий инструмент | C15: Фреза | E15: шт | H15: =IF(F15="","",F15*(1+IFERROR(G15,0))) | J15: =IFERROR(H15*I15,"") | K15: =IFERROR(J15*Продукт!B7,"")
A16: 10 | B16: Режущий и обрабатывающий инструмент | C16: Резец | E16: шт | H16: =IF(F16="","",F16*(1+IFERROR(G16,0))) | J16: =IFERROR(H16*I16,"") | K16: =IFERROR(J16*Продукт!B7,"")
A17: 11 | B17: Режущий и обрабатывающий инструмент | C17: Сверло | E17: шт | H17: =IF(F17="","",F17*(1+IFERROR(G17,0))) | J17: =IFERROR(H17*I17,"") | K17: =IFERROR(J17*Продукт!B7,"")
A18: 12 | B18: Режущий и обрабатывающий инструмент | H18: =IF(F18="","",F18*(1+IFERROR(G18,0))) | J18: =IFERROR(H18*I18,"") | K18: =IFERROR(J18*Продукт!B7,"")
A19: 13 | B19: Режущий и обрабатывающий инструмент | H19: =IF(F19="","",F19*(1+IFERROR(G19,0))) | J19: =IFERROR(H19*I19,"") | K19: =IFERROR(J19*Продукт!B7,"")
A20: 14 | B20: Режущий и обрабатывающий инструмент | H20: =IF(F20="","",F20*(1+IFERROR(G20,0))) | J20: =IFERROR(H20*I20,"") | K20: =IFERROR(J20*Продукт!B7,"")
A21: 15 | B21: Режущий и обрабатывающий инструмент | H21: =IF(F21="","",F21*(1+IFERROR(G21,0))) | J21: =IFERROR(H21*I21,"") | K21: =IFERROR(J21*Продукт!B7,"")
A22: 16 | B22: Режущий и обрабатывающий инструмент | H22: =IF(F22="","",F22*(1+IFERROR(G22,0))) | J22: =IFERROR(H22*I22,"") | K22: =IFERROR(J22*Продукт!B7,"")
A23: Контрольно-измерительный инструмент
A24: 17 | B24: Контрольно-измерительный инструмент | C24: Калибр / шаблон | E24: шт | H24: =IF(F24="","",F24*(1+IFERROR(G24,0))) | J24: =IFERROR(H24*I24,"") | K24: =IFERROR(J24*Продукт!B7,"")
A25: 18 | B25: Контрольно-измерительный инструмент | C25: Штангенциркуль | E25: шт | H25: =IF(F25="","",F25*(1+IFERROR(G25,0))) | J25: =IFERROR(H25*I25,"") | K25: =IFERROR(J25*Продукт!B7,"")
A26: 19 | B26: Контрольно-измерительный инструмент | H26: =IF(F26="","",F26*(1+IFERROR(G26,0))) | J26: =IFERROR(H26*I26,"") | K26: =IFERROR(J26*Продукт!B7,"")
A27: 20 | B27: Контрольно-измерительный инструмент | H27: =IF(F27="","",F27*(1+IFERROR(G27,0))) | J27: =IFERROR(H27*I27,"") | K27: =IFERROR(J27*Продукт!B7,"")
A28: 21 | B28: Контрольно-измерительный инструмент | H28: =IF(F28="","",F28*(1+IFERROR(G28,0))) | J28: =IFERROR(H28*I28,"") | K28: =IFERROR(J28*Продукт!B7,"")
A29: 22 | B29: Контрольно-измерительный инструмент | H29: =IF(F29="","",F29*(1+IFERROR(G29,0))) | J29: =IFERROR(H29*I29,"") | K29: =IFERROR(J29*Продукт!B7,"")
A30: 23 | B30: Контрольно-измерительный инструмент | H30: =IF(F30="","",F30*(1+IFERROR(G30,0))) | J30: =IFERROR(H30*I30,"") | K30: =IFERROR(J30*Продукт!B7,"")
A31: + ДОБАВИТЬ ЕЩЁ ПУНКТ (вставляйте строки выше или дописывайте здесь)
A32: 24 | H32: =IF(F32="","",F32*(1+IFERROR(G32,0))) | J32: =IFERROR(H32*I32,"") | K32: =IFERROR(J32*Продукт!B7,"")
A33: 25 | H33: =IF(F33="","",F33*(1+IFERROR(G33,0))) | J33: =IFERROR(H33*I33,"") | K33: =IFERROR(J33*Продукт!B7,"")
A34: 26 | H34: =IF(F34="","",F34*(1+IFERROR(G34,0))) | J34: =IFERROR(H34*I34,"") | K34: =IFERROR(J34*Продукт!B7,"")
A35: 27 | H35: =IF(F35="","",F35*(1+IFERROR(G35,0))) | J35: =IFERROR(H35*I35,"") | K35: =IFERROR(J35*Продукт!B7,"")
A36: 28 | H36: =IF(F36="","",F36*(1+IFERROR(G36,0))) | J36: =IFERROR(H36*I36,"") | K36: =IFERROR(J36*Продукт!B7,"")
A38: ИТОГО ПО КАТЕГОРИИ: | J38: =SUMIF(J5:J36,">0") -> 0 | K38: =SUMIF(K5:K36,">0") -> 0

Sheet Запчасти
A1: ЗАПАСНЫЕ ЧАСТИ (ЗИП)
A2: Заполните позиции по своему производству. Жёлтые ячейки — ключевые параметры. В конце есть блок "ДОБАВИТЬ ЕЩЁ ПУНКТ".
A4: № | B4: Подкатегория / группа | C4: Наименование позиции | D4: Артикул / код | E4: Ед. изм. | F4: Норма расхода на 1 ед. продукции | G4: % потерь / отходов | H4: Норма с учётом потерь | I4: Цена за единицу | J4: Стоимость на 1 ед. продукции | K4: Стоимость на весь объём выпуска | L4: Поставщик | M4: Срок поставки (дней) | N4: Мин. складской запас | O4: Примечание
A5: Механические запчасти
A6: 1 | B6: Механические запчасти | C6: Подшипник | E6: шт | H6: =IF(F6="","",F6*(1+IFERROR(G6,0))) | J6: =IFERROR(H6*I6,"") | K6: =IFERROR(J6*Продукт!B7,"")
A7: 2 | B7: Механические запчасти | C7: Ремень приводной | E7: шт | H7: =IF(F7="","",F7*(1+IFERROR(G7,0))) | J7: =IFERROR(H7*I7,"") | K7: =IFERROR(J7*Продукт!B7,"")
A8: 3 | B8: Механические запчасти | C8: Шестерня | E8: шт | H8: =IF(F8="","",F8*(1+IFERROR(G8,0))) | J8: =IFERROR(H8*I8,"") | K8: =IFERROR(J8*Продукт!B7,"")
A9: 4 | B9: Механические запчасти | C9: Шнек экструдера | E9: шт | H9: =IF(F9="","",F9*(1+IFERROR(G9,0))) | J9: =IFERROR(H9*I9,"") | K9: =IFERROR(J9*Продукт!B7,"")
A10: 5 | B10: Механические запчасти | H10: =IF(F10="","",F10*(1+IFERROR(G10,0))) | J10: =IFERROR(H10*I10,"") | K10: =IFERROR(J10*Продукт!B7,"")
A11: 6 | B11: Механические запчасти | H11: =IF(F11="","",F11*(1+IFERROR(G11,0))) | J11: =IFERROR(H11*I11,"") | K11: =IFERROR(J11*Продукт!B7,"")
A12: 7 | B12: Механические запчасти | H12: =IF(F12="","",F12*(1+IFERROR(G12,0))) | J12: =IFERROR(H12*I12,"") | K12: =IFERROR(J12*Продукт!B7,"")
A13: 8 | B13: Механические запчасти | H13: =IF(F13="","",F13*(1+IFERROR(G13,0))) | J13: =IFERROR(H13*I13,"") | K13: =IFERROR(J13*Продукт!B7,"")
A14: 9 | B14: Механические запчасти | H14: =IF(F14="","",F14*(1+IFERROR(G14,0))) | J14: =IFERROR(H14*I14,"") | K14: =IFERROR(J14*Продукт!B7,"")
A15: Электрические запчасти
A16: 10 | B16: Электрические запчасти | C16: Нагревательный элемент (ТЭН) | E16: шт | H16: =IF(F16="","",F16*(1+IFERROR(G16,0))) | J16: =IFERROR(H16*I16,"") | K16: =IFERROR(J16*Продукт!B7,"")
A17: 11 | B17: Электрические запчасти | C17: Датчик температуры | E17: шт | H17: =IF(F17="","",F17*(1+IFERROR(G17,0))) | J17: =IFERROR(H17*I17,"") | K17: =IFERROR(J17*Продукт!B7,"")
A18: 12 | B18: Электрические запчасти | C18: Реле / контактор | E18: шт | H18: =IF(F18="","",F18*(1+IFERROR(G18,0))) | J18: =IFERROR(H18*I18,"") | K18: =IFERROR(J18*Продукт!B7,"")
A19: 13 | B19: Электрические запчасти | H19: =IF(F19="","",F19*(1+IFERROR(G19,0))) | J19: =IFERROR(H19*I19,"") | K19: =IFERROR(J19*Продукт!B7,"")
A20: 14 | B20: Электрические запчасти | H20: =IF(F20="","",F20*(1+IFERROR(G20,0))) | J20: =IFERROR(H20*I20,"") | K20: =IFERROR(J20*Продукт!B7,"")
A21: 15 | B21: Электрические запчасти | H21: =IF(F21="","",F21*(1+IFERROR(G21,0))) | J21: =IFERROR(H21*I21,"") | K21: =IFERROR(J21*Продукт!B7,"")
A22: 16 | B22: Электрические запчасти | H22: =IF(F22="","",F22*(1+IFERROR(G22,0))) | J22: =IFERROR(H22*I22,"") | K22: =IFERROR(J22*Продукт!B7,"")
A23: 17 | B23: Электрические запчасти | H23: =IF(F23="","",F23*(1+IFERROR(G23,0))) | J23: =IFERROR(H23*I23,"") | K23: =IFERROR(J23*Продукт!B7,"")
A24: Пневматика и гидравлика
A25: 18 | B25: Пневматика и гидравлика | C25: Пневмоцилиндр | E25: шт | H25: =IF(F25="","",F25*(1+IFERROR(G25,0))) | J25: =IFERROR(H25*I25,"") | K25: =IFERROR(J25*Продукт!B7,"")
A26: 19 | B26: Пневматика и гидравлика | C26: Уплотнение / сальник | E26: шт | H26: =IF(F26="","",F26*(1+IFERROR(G26,0))) | J26: =IFERROR(H26*I26,"") | K26: =IFERROR(J26*Продукт!B7,"")
A27: 20 | B27: Пневматика и гидравлика | H27: =IF(F27="","",F27*(1+IFERROR(G27,0))) | J27: =IFERROR(H27*I27,"") | K27: =IFERROR(J27*Продукт!B7,"")
A28: 21 | B28: Пневматика и гидравлика | H28: =IF(F28="","",F28*(1+IFERROR(G28,0))) | J28: =IFERROR(H28*I28,"") | K28: =IFERROR(J28*Продукт!B7,"")
A29: 22 | B29: Пневматика и гидравлика | H29: =IF(F29="","",F29*(1+IFERROR(G29,0))) | J29: =IFERROR(H29*I29,"") | K29: =IFERROR(J29*Продукт!B7,"")
A30: 23 | B30: Пневматика и гидравлика | H30: =IF(F30="","",F30*(1+IFERROR(G30,0))) | J30: =IFERROR(H30*I30,"") | K30: =IFERROR(J30*Продукт!B7,"")
A31: 24 | B31: Пневматика и гидравлика | H31: =IF(F31="","",F31*(1+IFERROR(G31,0))) | J31: =IFERROR(H31*I31,"") | K31: =IFERROR(J31*Продукт!B7,"")
A32: + ДОБАВИТЬ ЕЩЁ ПУНКТ (вставляйте строки выше или дописывайте здесь)
A33: 25 | H33: =IF(F33="","",F33*(1+IFERROR(G33,0))) | J33: =IFERROR(H33*I33,"") | K33: =IFERROR(J33*Продукт!B7,"")
A34: 26 | H34: =IF(F34="","",F34*(1+IFERROR(G34,0))) | J34: =IFERROR(H34*I34,"") | K34: =IFERROR(J34*Продукт!B7,"")
A35: 27 | H35: =IF(F35="","",F35*(1+IFERROR(G35,0))) | J35: =IFERROR(H35*I35,"") | K35: =IFERROR(J35*Продукт!B7,"")
A36: 28 | H36: =IF(F36="","",F36*(1+IFERROR(G36,0))) | J36: =IFERROR(H36*I36,"") | K36: =IFERROR(J36*Продукт!B7,"")
A37: 29 | H37: =IF(F37="","",F37*(1+IFERROR(G37,0))) | J37: =IFERROR(H37*I37,"") | K37: =IFERROR(J37*Продукт!B7,"")
A39: ИТОГО ПО КАТЕГОРИИ: | J39: =SUMIF(J5:J37,">0") -> 0 | K39: =SUMIF(K5:K37,">0") -> 0

Sheet Расходники
A1: РАСХОДНЫЕ МАТЕРИАЛЫ ДЛЯ ОБОРУДОВАНИЯ
A2: Заполните позиции по своему производству. Жёлтые ячейки — ключевые параметры. В конце есть блок "ДОБАВИТЬ ЕЩЁ ПУНКТ".
A4: № | B4: Подкатегория / группа | C4: Наименование позиции | D4: Артикул / код | E4: Ед. изм. | F4: Норма расхода на 1 ед. продукции | G4: % потерь / отходов | H4: Норма с учётом потерь | I4: Цена за единицу | J4: Стоимость на 1 ед. продукции | K4: Стоимость на весь объём выпуска | L4: Поставщик | M4: Срок поставки (дней) | N4: Мин. складской запас | O4: Примечание
A5: Смазочные материалы
A6: 1 | B6: Смазочные материалы | C6: Масло индустриальное | E6: л | H6: =IF(F6="","",F6*(1+IFERROR(G6,0))) | J6: =IFERROR(H6*I6,"") | K6: =IFERROR(J6*Продукт!B7,"")
A7: 2 | B7: Смазочные материалы | C7: Смазка консистентная | E7: кг | H7: =IF(F7="","",F7*(1+IFERROR(G7,0))) | J7: =IFERROR(H7*I7,"") | K7: =IFERROR(J7*Продукт!B7,"")
A8: 3 | B8: Смазочные материалы | H8: =IF(F8="","",F8*(1+IFERROR(G8,0))) | J8: =IFERROR(H8*I8,"") | K8: =IFERROR(J8*Продукт!B7,"")
A9: 4 | B9: Смазочные материалы | H9: =IF(F9="","",F9*(1+IFERROR(G9,0))) | J9: =IFERROR(H9*I9,"") | K9: =IFERROR(J9*Продукт!B7,"")
A10: 5 | B10: Смазочные материалы | H10: =IF(F10="","",F10*(1+IFERROR(G10,0))) | J10: =IFERROR(H10*I10,"") | K10: =IFERROR(J10*Продукт!B7,"")
A11: 6 | B11: Смазочные материалы | H11: =IF(F11="","",F11*(1+IFERROR(G11,0))) | J11: =IFERROR(H11*I11,"") | K11: =IFERROR(J11*Продукт!B7,"")
A12: 7 | B12: Смазочные материалы | H12: =IF(F12="","",F12*(1+IFERROR(G12,0))) | J12: =IFERROR(H12*I12,"") | K12: =IFERROR(J12*Продукт!B7,"")
A13: Технические жидкости
A14: 8 | B14: Технические жидкости | C14: СОЖ (смазочно-охлаждающая жидкость) | E14: л | H14: =IF(F14="","",F14*(1+IFERROR(G14,0))) | J14: =IFERROR(H14*I14,"") | K14: =IFERROR(J14*Продукт!B7,"")
A15: 9 | B15: Технические жидкости | C15: Гидравлическая жидкость | E15: л | H15: =IF(F15="","",F15*(1+IFERROR(G15,0))) | J15: =IFERROR(H15*I15,"") | K15: =IFERROR(J15*Продукт!B7,"")
A16: 10 | B16: Технические жидкости | C16: Антифриз | E16: л | H16: =IF(F16="","",F16*(1+IFERROR(G16,0))) | J16: =IFERROR(H16*I16,"") | K16: =IFERROR(J16*Продукт!B7,"")
A17: 11 | B17: Технические жидкости | H17: =IF(F17="","",F17*(1+IFERROR(G17,0))) | J17: =IFERROR(H17*I17,"") | K17: =IFERROR(J17*Продукт!B7,"")
A18: 12 | B18: Технические жидкости | H18: =IF(F18="","",F18*(1+IFERROR(G18,0))) | J18: =IFERROR(H18*I18,"") | K18: =IFERROR(J18*Продукт!B7,"")
A19: 13 | B19: Технические жидкости | H19: =IF(F19="","",F19*(1+IFERROR(G19,0))) | J19: =IFERROR(H19*I19,"") | K19: =IFERROR(J19*Продукт!B7,"")
A20: 14 | B20: Технические жидкости | H20: =IF(F20="","",F20*(1+IFERROR(G20,0))) | J20: =IFERROR(H20*I20,"") | K20: =IFERROR(J20*Продукт!B7,"")
A21: 15 | B21: Технические жидкости | H21: =IF(F21="","",F21*(1+IFERROR(G21,0))) | J21: =IFERROR(H21*I21,"") | K21: =IFERROR(J21*Продукт!B7,"")
A22: Фильтры и очистка
A23: 16 | B23: Фильтры и очистка | C23: Фильтр воздушный | E23: шт | H23: =IF(F23="","",F23*(1+IFERROR(G23,0))) | J23: =IFERROR(H23*I23,"") | K23: =IFERROR(J23*Продукт!B7,"")
A24: 17 | B24: Фильтры и очистка | C24: Фильтр масляный | E24: шт | H24: =IF(F24="","",F24*(1+IFERROR(G24,0))) | J24: =IFERROR(H24*I24,"") | K24: =IFERROR(J24*Продукт!B7,"")
A25: 18 | B25: Фильтры и очистка | C25: Ветошь, салфетки технические | E25: кг | H25: =IF(F25="","",F25*(1+IFERROR(G25,0))) | J25: =IFERROR(H25*I25,"") | K25: =IFERROR(J25*Продукт!B7,"")
A26: 19 | B26: Фильтры и очистка | H26: =IF(F26="","",F26*(1+IFERROR(G26,0))) | J26: =IFERROR(H26*I26,"") | K26: =IFERROR(J26*Продукт!B7,"")
A27: 20 | B27: Фильтры и очистка | H27: =IF(F27="","",F27*(1+IFERROR(G27,0))) | J27: =IFERROR(H27*I27,"") | K27: =IFERROR(J27*Продукт!B7,"")
A28: 21 | B28: Фильтры и очистка | H28: =IF(F28="","",F28*(1+IFERROR(G28,0))) | J28: =IFERROR(H28*I28,"") | K28: =IFERROR(J28*Продукт!B7,"")
A29: 22 | B29: Фильтры и очистка | H29: =IF(F29="","",F29*(1+IFERROR(G29,0))) | J29: =IFERROR(H29*I29,"") | K29: =IFERROR(J29*Продукт!B7,"")
A30: 23 | B30: Фильтры и очистка | H30: =IF(F30="","",F30*(1+IFERROR(G30,0))) | J30: =IFERROR(H30*I30,"") | K30: =IFERROR(J30*Продукт!B7,"")
A31: + ДОБАВИТЬ ЕЩЁ ПУНКТ (вставляйте строки выше или дописывайте здесь)
A32: 24 | H32: =IF(F32="","",F32*(1+IFERROR(G32,0))) | J32: =IFERROR(H32*I32,"") | K32: =IFERROR(J32*Продукт!B7,"")
A33: 25 | H33: =IF(F33="","",F33*(1+IFERROR(G33,0))) | J33: =IFERROR(H33*I33,"") | K33: =IFERROR(J33*Продукт!B7,"")
A34: 26 | H34: =IF(F34="","",F34*(1+IFERROR(G34,0))) | J34: =IFERROR(H34*I34,"") | K34: =IFERROR(J34*Продукт!B7,"")
A35: 27 | H35: =IF(F35="","",F35*(1+IFERROR(G35,0))) | J35: =IFERROR(H35*I35,"") | K35: =IFERROR(J35*Продукт!B7,"")
A36: 28 | H36: =IF(F36="","",F36*(1+IFERROR(G36,0))) | J36: =IFERROR(H36*I36,"") | K36: =IFERROR(J36*Продукт!B7,"")
A38: ИТОГО ПО КАТЕГОРИИ: | J38: =SUMIF(J5:J36,">0") -> 0 | K38: =SUMIF(K5:K36,">0") -> 0

Sheet Энергоресурсы
A1: ЭНЕРГОРЕСУРСЫ (ЭНЕРГИЯ И КОММУНАЛКА)
A2: Заполните позиции по своему производству. Жёлтые ячейки — ключевые параметры. В конце есть блок "ДОБАВИТЬ ЕЩЁ ПУНКТ".
A4: № | B4: Подкатегория / группа | C4: Наименование позиции | D4: Артикул / код | E4: Ед. изм. | F4: Норма расхода на 1 ед. продукции | G4: % потерь / отходов | H4: Норма с учётом потерь | I4: Цена за единицу | J4: Стоимость на 1 ед. продукции | K4: Стоимость на весь объём выпуска | L4: Поставщик | M4: Срок поставки (дней) | N4: Мин. складской запас | O4: Примечание
A5: Электричество
A6: 1 | B6: Электричество | C6: Электроэнергия (производство) | E6: кВт·ч | H6: =IF(F6="","",F6*(1+IFERROR(G6,0))) | J6: =IFERROR(H6*I6,"") | K6: =IFERROR(J6*Продукт!B7,"")
A7: 2 | B7: Электричество | H7: =IF(F7="","",F7*(1+IFERROR(G7,0))) | J7: =IFERROR(H7*I7,"") | K7: =IFERROR(J7*Продукт!B7,"")
A8: 3 | B8: Электричество | H8: =IF(F8="","",F8*(1+IFERROR(G8,0))) | J8: =IFERROR(H8*I8,"") | K8: =IFERROR(J8*Продукт!B7,"")
A9: 4 | B9: Электричество | H9: =IF(F9="","",F9*(1+IFERROR(G9,0))) | J9: =IFERROR(H9*I9,"") | K9: =IFERROR(J9*Продукт!B7,"")
A10: 5 | B10: Электричество | H10: =IF(F10="","",F10*(1+IFERROR(G10,0))) | J10: =IFERROR(H10*I10,"") | K10: =IFERROR(J10*Продукт!B7,"")
A11: 6 | B11: Электричество | H11: =IF(F11="","",F11*(1+IFERROR(G11,0))) | J11: =IFERROR(H11*I11,"") | K11: =IFERROR(J11*Продукт!B7,"")
A12: Газ и пар
A13: 7 | B13: Газ и пар | C13: Природный газ | E13: м³ | H13: =IF(F13="","",F13*(1+IFERROR(G13,0))) | J13: =IFERROR(H13*I13,"") | K13: =IFERROR(J13*Продукт!B7,"")
A14: 8 | B14: Газ и пар | C14: Пар технологический | E14: т | H14: =IF(F14="","",F14*(1+IFERROR(G14,0))) | J14: =IFERROR(H14*I14,"") | K14: =IFERROR(J14*Продукт!B7,"")
A15: 9 | B15: Газ и пар | H15: =IF(F15="","",F15*(1+IFERROR(G15,0))) | J15: =IFERROR(H15*I15,"") | K15: =IFERROR(J15*Продукт!B7,"")
A16: 10 | B16: Газ и пар | H16: =IF(F16="","",F16*(1+IFERROR(G16,0))) | J16: =IFERROR(H16*I16,"") | K16: =IFERROR(J16*Продукт!B7,"")
A17: 11 | B17: Газ и пар | H17: =IF(F17="","",F17*(1+IFERROR(G17,0))) | J17: =IFERROR(H17*I17,"") | K17: =IFERROR(J17*Продукт!B7,"")
A18: 12 | B18: Газ и пар | H18: =IF(F18="","",F18*(1+IFERROR(G18,0))) | J18: =IFERROR(H18*I18,"") | K18: =IFERROR(J18*Продукт!B7,"")
A19: 13 | B19: Газ и пар | H19: =IF(F19="","",F19*(1+IFERROR(G19,0))) | J19: =IFERROR(H19*I19,"") | K19: =IFERROR(J19*Продукт!B7,"")
A20: Вода
A21: 14 | B21: Вода | C21: Вода питьевая / техническая | E21: м³ | H21: =IF(F21="","",F21*(1+IFERROR(G21,0))) | J21: =IFERROR(H21*I21,"") | K21: =IFERROR(J21*Продукт!B7,"")
A22: 15 | B22: Вода | C22: Вода очищенная / деминерализованная | E22: м³ | H22: =IF(F22="","",F22*(1+IFERROR(G22,0))) | J22: =IFERROR(H22*I22,"") | K22: =IFERROR(J22*Продукт!B7,"")
A23: 16 | B23: Вода | H23: =IF(F23="","",F23*(1+IFERROR(G23,0))) | J23: =IFERROR(H23*I23,"") | K23: =IFERROR(J23*Продукт!B7,"")
A24: 17 | B24: Вода | H24: =IF(F24="","",F24*(1+IFERROR(G24,0))) | J24: =IFERROR(H24*I24,"") | K24: =IFERROR(J24*Продукт!B7,"")
A25: 18 | B25: Вода | H25: =IF(F25="","",F25*(1+IFERROR(G25,0))) | J25: =IFERROR(H25*I25,"") | K25: =IFERROR(J25*Продукт!B7,"")
A26: 19 | B26: Вода | H26: =IF(F26="","",F26*(1+IFERROR(G26,0))) | J26: =IFERROR(H26*I26,"") | K26: =IFERROR(J26*Продукт!B7,"")
A27: 20 | B27: Вода | H27: =IF(F27="","",F27*(1+IFERROR(G27,0))) | J27: =IFERROR(H27*I27,"") | K27: =IFERROR(J27*Продукт!B7,"")
A28: Сжатый воздух и газы
A29: 21 | B29: Сжатый воздух и газы | C29: Сжатый воздух | E29: м³ | H29: =IF(F29="","",F29*(1+IFERROR(G29,0))) | J29: =IFERROR(H29*I29,"") | K29: =IFERROR(J29*Продукт!B7,"")
A30: 22 | B30: Сжатый воздух и газы | C30: Азот / аргон / прочие газы | E30: м³ | H30: =IF(F30="","",F30*(1+IFERROR(G30,0))) | J30: =IFERROR(H30*I30,"") | K30: =IFERROR(J30*Продукт!B7,"")
A31: 23 | B31: Сжатый воздух и газы | H31: =IF(F31="","",F31*(1+IFERROR(G31,0))) | J31: =IFERROR(H31*I31,"") | K31: =IFERROR(J31*Продукт!B7,"")
A32: 24 | B32: Сжатый воздух и газы | H32: =IF(F32="","",F32*(1+IFERROR(G32,0))) | J32: =IFERROR(H32*I32,"") | K32: =IFERROR(J32*Продукт!B7,"")
A33: 25 | B33: Сжатый воздух и газы | H33: =IF(F33="","",F33*(1+IFERROR(G33,0))) | J33: =IFERROR(H33*I33,"") | K33: =IFERROR(J33*Продукт!B7,"")
A34: 26 | B34: Сжатый воздух и газы | H34: =IF(F34="","",F34*(1+IFERROR(G34,0))) | J34: =IFERROR(H34*I34,"") | K34: =IFERROR(J34*Продукт!B7,"")
A35: 27 | B35: Сжатый воздух и газы | H35: =IF(F35="","",F35*(1+IFERROR(G35,0))) | J35: =IFERROR(H35*I35,"") | K35: =IFERROR(J35*Продукт!B7,"")
A36: + ДОБАВИТЬ ЕЩЁ ПУНКТ (вставляйте строки выше или дописывайте здесь)
A37: 28 | H37: =IF(F37="","",F37*(1+IFERROR(G37,0))) | J37: =IFERROR(H37*I37,"") | K37: =IFERROR(J37*Продукт!B7,"")
A38: 29 | H38: =IF(F38="","",F38*(1+IFERROR(G38,0))) | J38: =IFERROR(H38*I38,"") | K38: =IFERROR(J38*Продукт!B7,"")
A39: 30 | H39: =IF(F39="","",F39*(1+IFERROR(G39,0))) | J39: =IFERROR(H39*I39,"") | K39: =IFERROR(J39*Продукт!B7,"")
A40: 31 | H40: =IF(F40="","",F40*(1+IFERROR(G40,0))) | J40: =IFERROR(H40*I40,"") | K40: =IFERROR(J40*Продукт!B7,"")
A41: 32 | H41: =IF(F41="","",F41*(1+IFERROR(G41,0))) | J41: =IFERROR(H41*I41,"") | K41: =IFERROR(J41*Продукт!B7,"")
...

Sheet СИЗ и санитария
A1: СИЗ, СПЕЦОДЕЖДА, САНИТАРИЯ
A2: Заполните позиции по своему производству. Жёлтые ячейки — ключевые параметры. В конце есть блок "ДОБАВИТЬ ЕЩЁ ПУНКТ".
A4: № | B4: Подкатегория / группа | C4: Наименование позиции | D4: Артикул / код | E4: Ед. изм. | F4: Норма расхода на 1 ед. продукции | G4: % потерь / отходов | H4: Норма с учётом потерь | I4: Цена за единицу | J4: Стоимость на 1 ед. продукции | K4: Стоимость на весь объём выпуска | L4: Поставщик | M4: Срок поставки (дней) | N4: Мин. складской запас | O4: Примечание
A5: Средства индивидуальной защиты
A6: 1 | B6: Средства индивидуальной защиты | C6: Перчатки | E6: пара | H6: =IF(F6="","",F6*(1+IFERROR(G6,0))) | J6: =IFERROR(H6*I6,"") | K6: =IFERROR(J6*Продукт!B7,"")
A7: 2 | B7: Средства индивидуальной защиты | C7: Маска / респиратор | E7: шт | H7: =IF(F7="","",F7*(1+IFERROR(G7,0))) | J7: =IFERROR(H7*I7,"") | K7: =IFERROR(J7*Продукт!B7,"")
A8: 3 | B8: Средства индивидуальной защиты | C8: Защитные очки | E8: шт | H8: =IF(F8="","",F8*(1+IFERROR(G8,0))) | J8: =IFERROR(H8*I8,"") | K8: =IFERROR(J8*Продукт!B7,"")
A9: 4 | B9: Средства индивидуальной защиты | C9: Бахилы | E9: пара | H9: =IF(F9="","",F9*(1+IFERROR(G9,0))) | J9: =IFERROR(H9*I9,"") | K9: =IFERROR(J9*Продукт!B7,"")
A10: 5 | B10: Средства индивидуальной защиты | H10: =IF(F10="","",F10*(1+IFERROR(G10,0))) | J10: =IFERROR(H10*I10,"") | K10: =IFERROR(J10*Продукт!B7,"")
A11: 6 | B11: Средства индивидуальной защиты | H11: =IF(F11="","",F11*(1+IFERROR(G11,0))) | J11: =IFERROR(H11*I11,"") | K11: =IFERROR(J11*Продукт!B7,"")
A12: 7 | B12: Средства индивидуальной защиты | H12: =IF(F12="","",F12*(1+IFERROR(G12,0))) | J12: =IFERROR(H12*I12,"") | K12: =IFERROR(J12*Продукт!B7,"")
A13: 8 | B13: Средства индивидуальной защиты | H13: =IF(F13="","",F13*(1+IFERROR(G13,0))) | J13: =IFERROR(H13*I13,"") | K13: =IFERROR(J13*Продукт!B7,"")
A14: 9 | B14: Средства индивидуальной защиты | H14: =IF(F14="","",F14*(1+IFERROR(G14,0))) | J14: =IFERROR(H14*I14,"") | K14: =IFERROR(J14*Продукт!B7,"")
A15: Спецодежда
A16: 10 | B16: Спецодежда | C16: Халат / комбинезон | E16: шт | H16: =IF(F16="","",F16*(1+IFERROR(G16,0))) | J16: =IFERROR(H16*I16,"") | K16: =IFERROR(J16*Продукт!B7,"")
A17: 11 | B17: Спецодежда | C17: Обувь рабочая | E17: пара | H17: =IF(F17="","",F17*(1+IFERROR(G17,0))) | J17: =IFERROR(H17*I17,"") | K17: =IFERROR(J17*Продукт!B7,"")
A18: 12 | B18: Спецодежда | C18: Шапочка / косынка | E18: шт | H18: =IF(F18="","",F18*(1+IFERROR(G18,0))) | J18: =IFERROR(H18*I18,"") | K18: =IFERROR(J18*Продукт!B7,"")
A19: 13 | B19: Спецодежда | H19: =IF(F19="","",F19*(1+IFERROR(G19,0))) | J19: =IFERROR(H19*I19,"") | K19: =IFERROR(J19*Продукт!B7,"")
A20: 14 | B20: Спецодежда | H20: =IF(F20="","",F20*(1+IFERROR(G20,0))) | J20: =IFERROR(H20*I20,"") | K20: =IFERROR(J20*Продукт!B7,"")
A21: 15 | B21: Спецодежда | H21: =IF(F21="","",F21*(1+IFERROR(G21,0))) | J21: =IFERROR(H21*I21,"") | K21: =IFERROR(J21*Продукт!B7,"")
A22: 16 | B22: Спецодежда | H22: =IF(F22="","",F22*(1+IFERROR(G22,0))) | J22: =IFERROR(H22*I22,"") | K22: =IFERROR(J22*Продукт!B7,"")
A23: 17 | B23: Спецодежда | H23: =IF(F23="","",F23*(1+IFERROR(G23,0))) | J23: =IFERROR(H23*I23,"") | K23: =IFERROR(J23*Продукт!B7,"")
A24: Уборка и дезинфекция
A25: 18 | B25: Уборка и дезинфекция | C25: Моющее средство | E25: л | H25: =IF(F25="","",F25*(1+IFERROR(G25,0))) | J25: =IFERROR(H25*I25,"") | K25: =IFERROR(J25*Продукт!B7,"")
A26: 19 | B26: Уборка и дезинфекция | C26: Дезинфицирующее средство | E26: л | H26: =IF(F26="","",F26*(1+IFERROR(G26,0))) | J26: =IFERROR(H26*I26,"") | K26: =IFERROR(J26*Продукт!B7,"")
A27: 20 | B27: Уборка и дезинфекция | C27: Тряпки / мопы для уборки | E27: шт | H27: =IF(F27="","",F27*(1+IFERROR(G27,0))) | J27: =IFERROR(H27*I27,"") | K27: =IFERROR(J27*Продукт!B7,"")
